Workbook

Sheet PB_CACHE
A1: H4sIAAAAAAAEAM2QvU7DMBSF0wZEEDyEdyIr/QmlQxYCAokORalYqqo41hWx6tjBP0jpY/SFwY5SGFgYuYPvtaXz3eMTDIIg+HTlu6/LoTuel8zQ6lbKHVq1DWi0YKUiqo3RCyjNpMjGyTjFE5zgJEa55cYqyARYowiP0dKWnNEnaFdyByITlvNTzy++sdsOu+2xuADFCGd7UnLICa3g98vVSjYL+ADe3e4YNc6G04aOe9a7inJZN0SBih6Jrgq2hyAMosOgaLWBGueSc+h0Gj+AcBvosd+/W7fNtEfA62i97lWFUUy8xajWVCrOyp8Mpv77fwmgnM1IStPr0XwyheRmvtlEwz7u87AfTvzwH616cxdfCnA7mCcCAAA=

Sheet Composite Returns
A1: Composite Performance
A2: As of: | B2: 46295
A3: QDVD Composite
A4: Period Ending | B4: Value | C4: # of Accounts | D4: Net Quarterly Return | E4: Net Monthly Return | F4: Cumulative Net Return | G4: Cumulative Net Value | H4: Gross Quarterly Return | I4: Gross Monthly Return | J4: Cumulative Gross Return | K4: Cumulative Gross Value | L4: S&P 500 Quarterly Return | M4: S&P 500 Monthly Return | N4: S&P 500 Cumulative Return | O4: S&P 500 Cumulative Value | P4: S&P 500 HD Quarterly Return | Q4: S&P 500 HD Monthly Return | R4: S&P 500 HD Cumulative Return | S4: S&P 500 HD Cumulative Value
A5: 40359 | B5: 0 | C5: 0 | F5: 1 | G5: 100 | J5: 1 | K5: 100 | N5: 1 | O5: 100 | R5: 1 | S5: 100
A6: 40451 | B6: 6061795.8 | C6: 23 | D6: =E6 -> 0.1139 | E6: 0.1139 | F6: =(F5)*(E6+1) -> 1.1139 | G6: =G5*(1+E6) -> 111.39 | H6: =I6 -> 0.1183 | I6: 0.1183 | J6: =(J5)*(I6+1) -> 1.1183 | K6: =K5*(1+I6) -> 111.83 | L6: =M6 -> 0.113 | M6: 0.113 | N6: =(N5)*(M6+1) -> 1.113 | O6: =O5*(1+M6) -> 111.3 | P6: =Q6 -> 0.1278 | Q6: 0.1278 | R6: =(R5)*(Q6+1) -> 1.1278 | S6: =S5*(1+Q6) -> 112.78
A7: 40543 | B7: 4076736 | C7: 11 | D7: =E7 -> 0.0600388 | E7: 0.0600388 | F7: =(E6+1)*(E7+1)-1 -> 0.18077722 | G7: =G6*(1+E7) -> 118.07772 | H7: =I7 -> 0.06379359 | I7: 0.06379359 | J7: =(I6+1)*(I7+1)-1 -> 0.18964037 | K7: =K6*(1+I7) -> 118.96404 | L7: =M7 -> 0.1076 | M7: 0.1076 | N7: =(M6+1)*(M7+1)-1 -> 0.2327588 | O7: =O6*(1+M7) -> 123.27588 | P7: =Q7 -> 0.065 | Q7: 0.065 | R7: =(Q6+1)*(Q7+1)-1 -> 0.201107 | S7: =S6*(1+Q7) -> 120.1107
A8: 40633 | B8: 4192937.4 | C8: 9 | D8: =E8 -> 0.0475 | E8: 0.0475 | F8: =(F7+1)*(E8+1)-1 -> 0.23686414 | G8: =G7*(1+E8) -> 123.68641 | H8: =I8 -> 0.05079532 | I8: 0.05079532 | J8: =(J7+1)*(I8+1)-1 -> 0.25006854 | K8: =K7*(1+I8) -> 125.00685 | L8: =M8 -> 0.0591 | M8: 0.0591 | N8: =(N7+1)*(M8+1)-1 -> 0.30561485 | O8: =O7*(1+M8) -> 130.56148 | P8: =Q8 -> 0.0537 | Q8: 0.0537 | R8: =(R7+1)*(Q8+1)-1 -> 0.26560645 | S8: =S7*(1+Q8) -> 126.56064
A9: 40724 | B9: 4801649.9 | C9: 12 | D9: =E9 -> 0.0303 | E9: 0.0303 | F9: =(F8+1)*(E9+1)-1 -> 0.27434112 | G9: =G8*(1+E9) -> 127.43411 | H9: =I9 -> 0.03338181 | I9: 0.03338181 | J9: =(J8+1)*(I9+1)-1 -> 0.29179809 | K9: =K8*(1+I9) -> 129.17981 | L9: =M9 -> 0.001 | M9: 0.001 | N9: =(N8+1)*(M9+1)-1 -> 0.30692046 | O9: =O8*(1+M9) -> 130.69205 | P9: =Q9 -> 0.036 | Q9: 0.036 | R9: =(R8+1)*(Q9+1)-1 -> 0.31116828 | S9: =S8*(1+Q9) -> 131.11683
A10: 40816 | B10: 6082382.9 | C10: 14 | D10: =E10 -> -0.0693 | E10: -0.0693 | F10: =(F9+1)*(E10+1)-1 -> 0.18602928 | G10: =G9*(1+E10) -> 118.60293 | H10: =I10 -> -0.06649197 | I10: -0.06649197 | J10: =(J9+1)*(I10+1)-1 -> 0.20590389 | K10: =K9*(1+I10) -> 120.59039 | L10: =M10 -> -0.1387 | M10: -0.1387 | N10: =(N9+1)*(M10+1)-1 -> 0.12565059 | O10: =O9*(1+M10) -> 112.56506 | P10: =Q10 -> -0.0721 | Q10: -0.0721 | R10: =(R9+1)*(Q10+1)-1 -> 0.21663305 | S10: =S9*(1+Q10) -> 121.6633
A11: 40908 | B11: 8040005.2 | C11: 18 | D11: =E11 -> 0.0969 | E11: 0.0969 | F11: =(F10+1)*(E11+1)-1 -> 0.30095552 | G11: =G10*(1+E11) -> 130.09555 | H11: =I11 -> 0.10024867 | I11: 0.10024867 | J11: =(J10+1)*(I11+1)-1 -> 0.32679415 | K11: =K10*(1+I11) -> 132.67941 | L11: =M11 -> 0.118 | M11: 0.118 | N11: =(N10+1)*(M11+1)-1 -> 0.25847736 | O11: =O10*(1+M11) -> 125.84774 | P11: =Q11 -> 0.1096 | Q11: 0.1096 | R11: =(R10+1)*(Q11+1)-1 -> 0.34997603 | S11: =S10*(1+Q11) -> 134.9976
A12: 40999 | B12: 8885522.7 | C12: 20 | D12: =E12 -> 0.0461 | E12: 0.0461 | F12: =(F11+1)*(E12+1)-1 -> 0.36092957 | G12: =G11*(1+E12) -> 136.09296 | H12: =I12 -> 0.04903046 | I12: 0.04903046 | J12: =(J11+1)*(I12+1)-1 -> 0.39184747 | K12: =K11*(1+I12) -> 139.18475 | L12: =M12 -> 0.1258 | M12: 0.1258 | N12: =(N11+1)*(M12+1)-1 -> 0.41679381 | O12: =O11*(1+M12) -> 141.67938 | P12: =Q12 -> 0.0408 | Q12: 0.0408 | R12: =(R11+1)*(Q12+1)-1 -> 0.40505505 | S12: =S11*(1+Q12) -> 140.5055
A13: 41090 | B13: 9583833.2 | C13: 20 | D13: =E13 -> -0.001 | E13: -0.001 | F13: =(F12+1)*(E13+1)-1 -> 0.35956864 | G13: =G12*(1+E13) -> 135.95686 | H13: =I13 -> 0.00181657 | I13: 0.00181657 | J13: =(J12+1)*(I13+1)-1 -> 0.39437586 | K13: =K12*(1+I13) -> 139.43759 | L13: =M13 -> -0.0275 | M13: -0.0275 | N13: =(N12+1)*(M13+1)-1 -> 0.37783198 | O13: =O12*(1+M13) -> 137.7832 | P13: =Q13 -> 0.0174 | Q13: 0.0174 | R13: =(R12+1)*(Q13+1)-1 -> 0.42950301 | S13: =S12*(1+Q13) -> 142.9503
A14: 41182 | B14: 11217593 | C14: 22 | D14: =E14 -> 0.0261 | E14: 0.0261 | F14: =(F13+1)*(E14+1)-1 -> 0.39505338 | G14: =G13*(1+E14) -> 139.50534 | H14: =I14 -> 0.02894327 | I14: 0.02894327 | J14: =(J13+1)*(I14+1)-1 -> 0.43473366 | K14: =K13*(1+I14) -> 143.47337 | L14: =M14 -> 0.0635 | M14: 0.0635 | N14: =(N13+1)*(M14+1)-1 -> 0.46532432 | O14: =O13*(1+M14) -> 146.53243 | P14: =Q14 -> 0.0446 | Q14: 0.0446 | R14: =(R13+1)*(Q14+1)-1 -> 0.49325884 | S14: =S13*(1+Q14) -> 149.32588
A15: 41274 | B15: 12755462 | C15: 26 | D15: =E15 -> 0.003 | E15: 0.003 | F15: =(F14+1)*(E15+1)-1 -> 0.39923854 | G15: =G14*(1+E15) -> 139.92385 | H15: =I15 -> 0.00538271 | I15: 0.00538271 | J15: =(J14+1)*(I15+1)-1 -> 0.44245641 | K15: =K14*(1+I15) -> 144.24564 | L15: =M15 -> -0.0038 | M15: -0.0038 | N15: =(N14+1)*(M15+1)-1 -> 0.45975608 | O15: =O14*(1+M15) -> 145.97561 | P15: =Q15 -> -0.003 | Q15: -0.003 | R15: =(R14+1)*(Q15+1)-1 -> 0.48877906 | S15: =S14*(1+Q15) -> 148.87791
A16: 41364 | B16: 13909060 | C16: 27 | D16: =E16 -> 0.0696 | E16: 0.0696 | F16: =(F15+1)*(E16+1)-1 -> 0.49662554 | G16: =G15*(1+E16) -> 149.66255 | H16: =I16 -> 0.07222969 | I16: 0.07222969 | J16: =(J15+1)*(I16+1)-1 -> 0.54664459 | K16: =K15*(1+I16) -> 154.66446 | L16: =M16 -> 0.1061 | M16: 0.1061 | N16: =(N15+1)*(M16+1)-1 -> 0.6146362 | O16: =O15*(1+M16) -> 161.46362 | P16: =Q16 -> 0.1368 | Q16: 0.1368 | R16: =(R15+1)*(Q16+1)-1 -> 0.69244404 | S16: =S15*(1+Q16) -> 169.2444
A17: 41455 | B17: 15783414 | C17: 30 | D17: =E17 -> 0.0139 | E17: 0.0139 | F17: =(F16+1)*(E17+1)-1 -> 0.51742864 | G17: =G16*(1+E17) -> 151.74286 | H17: =I17 -> 0.01647812 | I17: 0.01647812 | J17: =(J16+1)*(I17+1)-1 -> 0.57213039 | K17: =K16*(1+I17) -> 157.21304 | L17: =M17 -> 0.0291 | M17: 0.0291 | N17: =(N16+1)*(M17+1)-1 -> 0.66162212 | O17: =O16*(1+M17) -> 166.16221 | P17: =Q17 -> 0.022 | Q17: 0.022 | R17: =(R16+1)*(Q17+1)-1 -> 0.72967781 | S17: =S16*(1+Q17) -> 172.96778
A18: 41547 | B18: 17822735 | C18: 38 | D18: =E18 -> 0.0357 | E18: 0.0357 | F18: =(F17+1)*(E18+1)-1 -> 0.57160084 | G18: =G17*(1+E18) -> 157.16008 | H18: =I18 -> 0.03843533 | I18: 0.03843533 | J18: =(J17+1)*(I18+1)-1 -> 0.63255574 | K18: =K17*(1+I18) -> 163.25557 | L18: =M18 -> 0.0524 | M18: 0.0524 | N18: =(N17+1)*(M18+1)-1 -> 0.74869112 | O18: =O17*(1+M18) -> 174.86911 | P18: =Q18 -> 0.03 | Q18: 0.03 | R18: =(R17+1)*(Q18+1)-1 -> 0.78156814 | S18: =S17*(1+Q18) -> 178.15681
A19: 41639 | B19: 14943323 | C19: 37 | D19: =E19 -> 0.0672 | E19: 0.0672 | F19: =(F18+1)*(E19+1)-1 -> 0.67721242 | G19: =G18*(1+E19) -> 167.72124 | H19: =I19 -> 0.06994446 | I19: 0.06994446 | J19: =(J18+1)*(I19+1)-1 -> 0.74674397 | K19: =K18*(1+I19) -> 174.6744 | L19: =M19 -> 0.1051 | M19: 0.1051 | N19: =(N18+1)*(M19+1)-1 -> 0.93247855 | O19: =O18*(1+M19) -> 193.24786 | P19: =Q19 -> 0.0702 | Q19: 0.0702 | R19: =(R18+1)*(Q19+1)-1 -> 0.90663423 | S19: =S18*(1+Q19) -> 190.66342
... A22: 41912 | B22: 32649429 | C22: 57 | D22: =E22 -> -0.00866 | E22: -0.00866 | F22: =(F21+1)*(E22+1)-1 -> 0.77523102 | G22: =G21*(1+E22) -> 177.5231 | H22: =I22 -> -0.0063 | I22: -0.0063 | J22: =(J21+1)*(I22+1)-1 -> 0.86329429 | K22: =K21*(1+I22) -> 186.32943 | L22: =M22 -> 0.0113 | M22: 0.0113 | N22: =(N21+1)*(M22+1)-1 -> 1.0937427 | O22: =O21*(1+M22) -> 209.37427 | P22: =Q22 -> -0.0177 | Q22: -0.0177 | R22: =(R21+1)*(Q22+1)-1 -> 1.1241938 | S22: =S21*(1+Q22) -> 212.41938
A23: 41943 | B23: 34597235 | C23: 60 | E23: 0.008 | F23: =(F22+1)*(E23+1)-1 -> 0.78943287 | G23: =G22*(1+E23) -> 178.94329 | I23: 0.0095 | J23: =(J22+1)*(I23+1)-1 -> 0.88099558 | K23: =K22*(1+I23) -> 188.09956 | M23: 0.0244 | N23: =(N22+1)*(M23+1)-1 -> 1.14483 | O23: =O22*(1+M23) -> 214.483 | Q23: 0.056978376 | R23: =(R22+1)*(Q23+1)-1 -> 1.2452269 | S23: =S22*(1+Q23) -> 224.52269
A24: 41973 | B24: 35908254 | C24: 63 | E24: 0.0207 | F24: =(F23+1)*(E24+1)-1 -> 0.82647413 | G24: =G23*(1+E24) -> 182.64741 | I24: 0.0212 | J24: =(J23+1)*(I24+1)-1 -> 0.92087269 | K24: =K23*(1+I24) -> 192.08727 | M24: 0.0269 | N24: =(N23+1)*(M24+1)-1 -> 1.2025259 | O24: =O23*(1+M24) -> 220.25259 | Q24: 0.024186945 | R24: =(R23+1)*(Q24+1)-1 -> 1.2995321 | S24: =S23*(1+Q24) -> 229.95321
A25: 42004 | B25: 35810154 | C25: 65 | D25: =(1+E23)*(1+E24)*(1+E25)-1 -> 0.020531789 | E25: -0.0081 | F25: =(F24+1)*(E25+1)-1 -> 0.81167968 | G25: =G24*(1+E25) -> 181.16797 | H25: =(1+I23)*(1+I24)*(1+I25)-1 -> 0.02316964 | I25: -0.0075 | J25: =(J24+1)*(I25+1)-1 -> 0.90646614 | K25: =K24*(1+I25) -> 190.64661 | L25: =(1+M23)*(1+M24)*(1+M25)-1 -> 0.049326469 | M25: -0.0025 | N25: =(N24+1)*(M25+1)-1 -> 1.1970196 | O25: =O24*(1+M25) -> 219.70196 | P25: =(1+Q23)*(1+Q24)*(1+Q25)-1 -> 0.096594794 | Q25: 0.012979932 | R25: =(R24+1)*(Q25+1)-1 -> 1.3293798 | S25: =S24*(1+Q25) -> 232.93798
A26: 42035 | B26: 34857002 | C26: 65 | E26: -0.0287 | F26: =(F25+1)*(E26+1)-1 -> 0.75968448 | G26: =G25*(1+E26) -> 175.96845 | I26: -0.0273 | J26: =(J25+1)*(I26+1)-1 -> 0.85441962 | K26: =K25*(1+I26) -> 185.44196 | M26: -0.03 | N26: =(N25+1)*(M26+1)-1 -> 1.131109 | O26: =O25*(1+M26) -> 213.1109 | Q26: 0.0063184954 | R26: =(R25+1)*(Q26+1)-1 -> 1.344098 | S26: =S25*(1+Q26) -> 234.4098
A27: 42063 | B27: 37028776 | C27: 66 | E27: 0.0542 | F27: =(F26+1)*(E27+1)-1 -> 0.85505938 | G27: =G26*(1+E27) -> 185.50594 | I27: 0.0548 | J27: =(J26+1)*(I27+1)-1 -> 0.95604181 | K27: =K26*(1+I27) -> 195.60418 | M27: 0.0575 | N27: =(N26+1)*(M27+1)-1 -> 1.2536478 | O27: =O26*(1+M27) -> 225.36478 | Q27: 0.0044152402 | R27: =(R26+1)*(Q27+1)-1 -> 1.3544478 | S27: =S26*(1+Q27) -> 235.44478
A28: 42094 | B28: 36514229 | C28: 67 | D28: =(1+E26)*(1+E27)*(1+E28)-1 -> 0.0042847264 | E28: -0.0192 | F28: =(F27+1)*(E28+1)-1 -> 0.81944224 | G28: =G27*(1+E28) -> 181.94422 | H28: =(1+I26)*(1+I27)*(1+I28)-1 -> 0.0068176859 | I28: -0.0187 | J28: =(J27+1)*(I28+1)-1 -> 0.91946383 | K28: =K27*(1+I28) -> 191.94638 | L28: =(1+M26)*(1+M27)*(1+M28)-1 -> 0.009567755 | M28: -0.0158 | N28: =(N27+1)*(M28+1)-1 -> 1.2180402 | O28: =O27*(1+M28) -> 221.80402 | P28: =(1+Q26)*(1+Q27)*(1+Q28)-1 -> -0.0068523525 | Q28: -0.017426449 | R28: =(R27+1)*(Q28+1)-1 -> 1.3134181 | S28: =S27*(1+Q28) -> 231.34181
A29: 42124 | B29: 36883499 | C29: 66 | E29: 0.0187 | F29: =(F28+1)*(E29+1)-1 -> 0.85346581 | G29: =G28*(1+E29) -> 185.34658 | I29: 0.0201 | J29: =(J28+1)*(I29+1)-1 -> 0.95804505 | K29: =K28*(1+I29) -> 195.80451 | M29: 0.0096 | N29: =(N28+1)*(M29+1)-1 -> 1.2393334 | O29: =O28*(1+M29) -> 223.93334 | Q29: 0.017766748 | R29: =(R28+1)*(Q29+1)-1 -> 1.35452 | S29: =S28*(1+Q29) -> 235.452
A30: 42155 | B30: 36877409 | C30: 66 | E30: -0.006 | F30: =(F29+1)*(E30+1)-1 -> 0.84234501 | G30: =G29*(1+E30) -> 184.2345 | I30: -0.0055 | J30: =(J29+1)*(I30+1)-1 -> 0.94727581 | K30: =K29*(1+I30) -> 194.72758 | M30: 0.0129 | N30: =(N29+1)*(M30+1)-1 -> 1.2682208 | O30: =O29*(1+M30) -> 226.82208 | Q30: -0.0097946337 | R30: =(R29+1)*(Q30+1)-1 -> 1.3314584 | S30: =S29*(1+Q30) -> 233.14584
A31: 42185 | B31: 35761754 | C31: 64 | D31: =(1+E29)*(1+E30)*(1+E31)-1 -> -0.013030671 | E31: -0.0253 | F31: =(F30+1)*(E31+1)-1 -> 0.79573368 | G31: =G30*(1+E31) -> 179.57337 | H31: =(1+I29)*(1+I30)*(1+I31)-1 -> -0.010568439 | I31: -0.0247 | J31: =(J30+1)*(I31+1)-1 -> 0.89917809 | K31: =K30*(1+I31) -> 189.91781 | L31: =(1+M29)*(1+M30)*(1+M31)-1 -> 0.0027849375 | M31: -0.0194 | N31: =(N30+1)*(M31+1)-1 -> 1.2242173 | O31: =O30*(1+M31) -> 222.42173 | P31: =(1+Q29)*(1+Q30)*(1+Q31)-1 -> -0.030813629 | Q31: -0.038312957 | R31: =(R30+1)*(Q31+1)-1 -> 1.2421333 | S31: =S30*(1+Q31) -> 224.21333
A32: 42216 | B32: 37638439 | C32: 67 | E32: 0.003 | F32: =(F31+1)*(E32+1)-1 -> 0.80112088 | G32: =G31*(1+E32) -> 180.11209 | I32: 0.0044 | J32: =(J31+1)*(I32+1)-1 -> 0.90753448 | K32: =K31*(1+I32) -> 190.75345 | M32: 0.0209 | N32: =(N31+1)*(M32+1)-1 -> 1.2707034 | O32: =O31*(1+M32) -> 227.07034 | Q32: 0.010507682 | R32: =(R31+1)*(Q32+1)-1 -> 1.2656929 | S32: =S31*(1+Q32) -> 226.56929
A33: 42247 | B33: 35588804 | C33: 67 | E33: -0.0545 | F33: =(F32+1)*(E33+1)-1 -> 0.7029598 | G33: =G32*(1+E33) -> 170.29598 | I33: -0.054 | J33: =(J32+1)*(I33+1)-1 -> 0.80452762 | K33: =K32*(1+I33) -> 180.45276 | M33: -0.0603 | N33: =(N32+1)*(M33+1)-1 -> 1.13378 | O33: =O32*(1+M33) -> 213.378 | Q33: -0.036738389 | R33: =(R32+1)*(Q33+1)-1 -> 1.182455 | S33: =S32*(1+Q33) -> 218.2455
A34: 42277 | B34: 36294524 | C34: 69 | D34: =(1+E32)*(1+E33)*(1+E34)-1 -> -0.064181542 | E34: -0.0132 | F34: =(F33+1)*(E34+1)-1 -> 0.68048073 | G34: =G33*(1+E34) -> 168.04807 | H34: =(1+I32)*(1+I33)*(1+I34)-1 -> -0.061809646 | I34: -0.0126 | J34: =(J33+1)*(I34+1)-1 -> 0.78179057 | K34: =K33*(1+I34) -> 178.17906 | L34: =(1+M32)*(1+M33)*(1+M34)-1 -> -0.064355961 | M34: -0.0247 | N34: =(N33+1)*(M34+1)-1 -> 1.0810756 | O34: =O33*(1+M34) -> 208.10756 | P34: =(1+Q32)*(1+Q33)*(1+Q34)-1 -> -0.030242494 | Q34: -0.0037248963 | R34: =(R33+1)*(Q34+1)-1 -> 1.1743256 | S34: =S33*(1+Q34) -> 217.43256
A35: 42308 | B35: 36267237 | C35: 64 | E35: 0.0693 | F35: =(F34+1)*(E35+1)-1 -> 0.79693804 | G35: =G34*(1+E35) -> 179.6938 | I35: 0.0707 | J35: =(J34+1)*(I35+1)-1 -> 0.90776316 | K35: =K34*(1+I35) -> 190.77632 | M35: 0.0844 | N35: =(N34+1)*(M35+1)-1 -> 1.2567184 | O35: =O34*(1+M35) -> 225.67184 | Q35: 0.063093659 | R35: =(R34+1)*(Q35+1)-1 -> 1.3115118 | S35: =S34*(1+Q35) -> 231.15118
A36: 42338 | B36: 37087727 | C36: 68 | E36: -0.0063 | F36: =(F35+1)*(E36+1)-1 -> 0.78561733 | G36: =G35*(1+E36) -> 178.56173 | I36: -0.0058 | J36: =(J35+1)*(I36+1)-1 -> 0.89669814 | K36: =K35*(1+I36) -> 189.66981 | M36: 0.003 | N36: =(N35+1)*(M36+1)-1 -> 1.2634886 | O36: =O35*(1+M36) -> 226.34886 | Q36: -0.0094158449 | R36: =(R35+1)*(Q36+1)-1 -> 1.2897469 | S36: =S35*(1+Q36) -> 228.97469
A37: 42369 | B37: 38338078 | C37: 69 | D37: =(1+E35)*(1+E36)*(1+E37)-1 -> 0.047581266 | E37: -0.0141 | F37: =(F36+1)*(E37+1)-1 -> 0.76044013 | G37: =G36*(1+E37) -> 176.04401 | H37: =(1+I35)*(1+I36)*(1+I37)-1 -> 0.050119326 | I37: -0.0135 | J37: =(J36+1)*(I37+1)-1 -> 0.87109271 | K37: =K36*(1+I37) -> 187.10927 | L37: =(1+M35)*(1+M36)*(1+M37)-1 -> 0.070468279 | M37: -0.0158 | N37: =(N36+1)*(M37+1)-1 -> 1.2277254 | O37: =O36*(1+M37) -> 222.77254 | P37: =(1+Q35)*(1+Q36)*(1+Q37)-1 -> 0.045639897 | Q37: -0.0070686087 | R37: =(R36+1)*(Q37+1)-1 -> 1.2735616 | S37: =S36*(1+Q37) -> 227.35616
A38: 42400 | B38: 43403530 | C38: 73 | E38: -0.0277 | F38: =(F37+1)*(E38+1)-1 -> 0.71167594 | G38: =G37*(1+E38) -> 171.16759 | I38: -0.0266 | J38: =(J37+1)*(I38+1)-1 -> 0.82132164 | K38: =K37*(1+I38) -> 182.13216 | M38: -0.0496 | N38: =(N37+1)*(M38+1)-1 -> 1.1172303 | O38: =O37*(1+M38) -> 211.72303 | Q38: -0.010880674 | R38: =(R37+1)*(Q38+1)-1 -> 1.2488237 | S38: =S37*(1+Q38) -> 224.88237
A39: 42429 | B39: 43282075 | C39: 73 | E39: 0.0088 | F39: =(F38+1)*(E39+1)-1 -> 0.72673868 | G39: =G38*(1+E39) -> 172.67387 | I39: 0.0092 | J39: =(J38+1)*(I39+1)-1 -> 0.8380778 | K39: =K38*(1+I39) -> 183.80778 | M39: -0.0013 | N39: =(N38+1)*(M39+1)-1 -> 1.1144779 | O39: =O38*(1+M39) -> 211.44779 | Q39: 0.030301475 | R39: =(R38+1)*(Q39+1)-1 -> 1.3169664 | S39: =S38*(1+Q39) -> 231.69664
A40: 42460 | B40: 46942877 | C40: 74 | D40: =(1+E38)*(1+E39)*(1+E40)-1 -> 0.039315272 | E40: 0.0596 | F40: =(F39+1)*(E40+1)-1 -> 0.82965231 | G40: =G39*(1+E40) -> 182.96523 | H40: =(1+I38)*(1+I39)*(1+I40)-1 -> 0.041493068 | I40: 0.0602 | J40: =(J39+1)*(I40+1)-1 -> 0.94873009 | K40: =K39*(1+I40) -> 194.87301 | L40: =(1+M38)*(1+M39)*(1+M40)-1 -> 0.013517832 | M40: 0.0678 | N40: =(N39+1)*(M40+1)-1 -> 1.2578395 | O40: =O39*(1+M40) -> 225.78395 | P40: =(1+Q38)*(1+Q39)*(1+Q40)-1 -> 0.11327978 | Q40: 0.092424201 | R40: =(R39+1)*(Q40+1)-1 -> 1.5311102 | S40: =S39*(1+Q40) -> 253.11102
A41: 42490 | B41: 47161051 | C41: 73 | E41: 0.0016 | F41: =(F40+1)*(E41+1)-1 -> 0.83257975 | G41: =G40*(1+E41) -> 183.25798 | I41: 0.003 | J41: =(J40+1)*(I41+1)-1 -> 0.95457628 | K41: =K40*(1+I41) -> 195.45763 | M41: 0.0039 | N41: =(N40+1)*(M41+1)-1 -> 1.266645 | O41: =O40*(1+M41) -> 226.6645 | Q41: 0.013253809 | R41: =(R40+1)*(Q41+1)-1 -> 1.564657 | S41: =S40*(1+Q41) -> 256.4657
A42: 42521 | B42: 49422177 | C42: 79 | E42: 0.0036 | F42: =(F41+1)*(E42+1)-1 -> 0.83917704 | G42: =G41*(1+E42) -> 183.9177 | I42: 0.0042 | J42: =(J41+1)*(I42+1)-1 -> 0.9627855 | K42: =K41*(1+I42) -> 196.27855 | M42: 0.018 | N42: =(N41+1)*(M42+1)-1 -> 1.3074446 | O42: =O41*(1+M42) -> 230.74446 | Q42: 0.00048460142 | R42: =(R41+1)*(Q42+1)-1 -> 1.5658999 | S42: =S41*(1+Q42) -> 256.58999
...

Sheet Period Returns
A1: Composite Performance
B2: =+B3-80-DAY(B3-80) -> 46203 | C2: =DATE(YEAR(C3)-1,12,31) -> 46022 | D2: =DATE(YEAR(D3)-D4,MONTH(D3),DAY(D3)) -> 45930 | E2: =DATE(YEAR(E3)-E4,MONTH(E3),DAY(E3)) -> 45199 | F2: =DATE(YEAR(F3)-F4,MONTH(F3),DAY(F3)) -> 44469 | G2: =DATE(YEAR(G3)-G4,MONTH(G3),DAY(G3)) -> 42643
B3: ='Composite Returns'!$B$2 -> 46295 | C3: ='Composite Returns'!$B$2 -> 46295 | D3: ='Composite Returns'!$B$2 -> 46295 | E3: ='Composite Returns'!$B$2 -> 46295 | F3: ='Composite Returns'!$B$2 -> 46295 | G3: ='Composite Returns'!$B$2 -> 46295
C4: 1 | D4: 1 | E4: 3 | F4: 5 | G4: 10
A5: Composite/Index | B5: Quarter | C5: YTD | D5: One Year | E5: Three Year | F5: Five Year | G5: Ten Year | H5: Since Inception* | I5: Since Inception (Annualized) | J5: Incept Years | K5: Inception
A6: Quality Dividend Strategy | B6: =(VLOOKUP(B$3,'Composite Returns'!$A$5:$K167,11,0)/VLOOKUP(B$2,'Composite Returns'!$A$5:$K167,11,0))-1 -> 0.026575617 | C6: =(VLOOKUP(C$3,'Composite Returns'!$A$5:$K167,11,0)/VLOOKUP(C$2,'Composite Returns'!$A$5:$K167,11,0))-1 -> 0.14210249 | D6: =(VLOOKUP(D$3,'Composite Returns'!$A$5:$K167,11,0)/VLOOKUP(D$2,'Composite Returns'!$A$5:$K167,11,0))-1 -> 0.16982316 | E6: =(VLOOKUP(E$3,'Composite Returns'!$A$5:$K167,11,0)/VLOOKUP(E$2,'Composite Returns'!$A$5:$K167,11,0))^(1/E$4)-1 -> 0.11257402 | F6: =(VLOOKUP(F$3,'Composite Returns'!$A$5:$K167,11,0)/VLOOKUP(F$2,'Composite Returns'!$A$5:$K167,11,0))^(1/F$4)-1 -> 0.080203968 | G6: =(VLOOKUP(G$3,'Composite Returns'!$A$5:$K167,11,0)/VLOOKUP(G$2,'Composite Returns'!$A$5:$K167,11,0))^(1/G$4)-1 -> 0.096277137 | H6: =(VLOOKUP(B$3,'Composite Returns'!$A$5:$K167,11,0)/VLOOKUP(K6,'Composite Returns'!$A$5:$K167,11,0))-1 -> 4.122101 | I6: =(1+H6)^(1/J6)-1 -> 0.10573825 | J6: =+(B$3-K6)/365.242 -> 16.252238 | K6: 40359
A7: Quality SMID Dividend Strategy | B7: =(VLOOKUP(B$3,'Composite Returns'!$A$171:$K313,11,0)/VLOOKUP(B$2,'Composite Returns'!$A$171:$K313,11,0))-1 -> -0.0072611439 | C7: =(VLOOKUP(C$3,'Composite Returns'!$A$171:$K313,11,0)/VLOOKUP(C$2,'Composite Returns'!$A$171:$K313,11,0))-1 -> 0.032548541 | D7: =(VLOOKUP(D$3,'Composite Returns'!$A$171:$K313,11,0)/VLOOKUP(D$2,'Composite Returns'!$A$171:$K313,11,0))-1 -> 0.078966737 | E7: =(VLOOKUP(E$3,'Composite Returns'!$A$171:$K313,11,0)/VLOOKUP(E$2,'Composite Returns'!$A$171:$K313,11,0))^(1/E$4)-1 -> 0.087889473 | F7: =(VLOOKUP(F$3,'Composite Returns'!$A$171:$K313,11,0)/VLOOKUP(F$2,'Composite Returns'!$A$171:$K313,11,0))^(1/F$4)-1 -> 0.052720635 | G7: =(VLOOKUP(G$3,'Composite Returns'!$A$171:$K313,11,0)/VLOOKUP(G$2,'Composite Returns'!$A$171:$K313,11,0))^(1/G$4)-1 -> 0.077075035 | H7: =(VLOOKUP(B$3,'Composite Returns'!$A$171:$K313,11,0)/VLOOKUP(K7,'Composite Returns'!$A$171:$K313,11,0))-1 -> 1.455011 | I7: =(1+H7)^(1/J7)-1 -> 0.079445275 | J7: =+(B$3-K7)/365.242 -> 11.748375 | K7: 42004
A8: Quality All-Cap Dividend Strategy | B8: =(VLOOKUP(B$3,'Composite Returns'!$A$317:$K447,11,0)/VLOOKUP(B$2,'Composite Returns'!$A$317:$K447,11,0))-1 -> 0.025423552 | C8: =(VLOOKUP(C$3,'Composite Returns'!$A$317:$K447,11,0)/VLOOKUP(C$2,'Composite Returns'!$A$317:$K447,11,0))-1 -> 0.10186571 | D8: =(VLOOKUP(D$3,'Composite Returns'!$A$317:$K447,11,0)/VLOOKUP(D$2,'Composite Returns'!$A$317:$K447,11,0))-1 -> 0.12753617 | E8: =(VLOOKUP(E$3,'Composite Returns'!$A$317:$K447,11,0)/VLOOKUP(E$2,'Composite Returns'!$A$317:$K447,11,0))^(1/E$4)-1 -> 0.10505537 | F8: =(VLOOKUP(F$3,'Composite Returns'!$A$317:$K447,11,0)/VLOOKUP(F$2,'Composite Returns'!$A$317:$K447,11,0))^(1/F$4)-1 -> 0.069894708 | G8: =(VLOOKUP(G$3,'Composite Returns'!$A$317:$K447,11,0)/VLOOKUP(G$2,'Composite Returns'!$A$317:$K447,11,0))^(1/G$4)-1 -> 0.098741397 | H8: =(VLOOKUP(B$3,'Composite Returns'!$A$317:$K447,11,0)/VLOOKUP(K8,'Composite Returns'!$A$317:$K447,11,0))-1 -> 1.8662029 | I8: =(1+H8)^(1/J8)-1 -> 0.10291994 | J8: =+(B$3-K8)/365.242 -> 10.749038 | K8: 42369
A9: Oregon Dividend Strategy | B9: =(VLOOKUP(B$3,'Composite Returns'!$A$451:$K560,11,0)/VLOOKUP(B$2,'Composite Returns'!$A$451:$K560,11,0))-1 -> 0.005282879 | C9: =(VLOOKUP(C$3,'Composite Returns'!$A$451:$K560,11,0)/VLOOKUP(C$2,'Composite Returns'!$A$451:$K560,11,0))-1 -> 0.067526256 | D9: =(VLOOKUP(D$3,'Composite Returns'!$A$451:$K560,11,0)/VLOOKUP(D$2,'Composite Returns'!$A$451:$K560,11,0))-1 -> 0.078398303 | E9: =(VLOOKUP(E$3,'Composite Returns'!$A$451:$K560,11,0)/VLOOKUP(E$2,'Composite Returns'!$A$451:$K560,11,0))^(1/E$4)-1 -> 0.088433436 | F9: =(VLOOKUP(F$3,'Composite Returns'!$A$451:$K560,11,0)/VLOOKUP(F$2,'Composite Returns'!$A$451:$K560,11,0))^(1/F$4)-1 -> 0.055610552 | G9: - | H9: =(VLOOKUP(B$3,'Composite Returns'!$A$451:$K560,11,0)/VLOOKUP(K9,'Composite Returns'!$A$451:$K560,11,0))-1 -> 1.107634 | I9: =(1+H9)^(1/J9)-1 -> 0.086373571 | J9: =+(B$3-K9)/365.242 -> 8.9995127 | K9: 43008
A10: Dividend Core Plus Strategy | B10: =(VLOOKUP(B$3,'Composite Returns'!$A$564:$K$574,11,0)/VLOOKUP(B$2,'Composite Returns'!$A$564:$K$574,11,0))-1 -> 0.022960664 | C10: =(VLOOKUP(C$3,'Composite Returns'!$A$564:$K$574,11,0)/VLOOKUP(C$2,'Composite Returns'!$A$564:$K$574,11,0))-1 -> 0.14768803 | D10: - | E10: - | F10: - | G10: - | H10: =(VLOOKUP(B$3,'Composite Returns'!$A$564:$K$574,11,0)/VLOOKUP(K10,'Composite Returns'!$A$564:$K$574,11,0))-1 -> 0.14768803 | I10: - | J10: =+(B$3-K10)/365.242 -> 0.74744964 | K10: 46022
A11: Balanced | B11: =(VLOOKUP(B$3,'Composite Returns'!$A$578:$K740,11,0)/VLOOKUP(B$2,'Composite Returns'!$A$578:$K740,11,0))-1 -> 0.021798781 | C11: =(VLOOKUP(C$3,'Composite Returns'!$A$578:$K740,11,0)/VLOOKUP(C$2,'Composite Returns'!$A$578:$K740,11,0))-1 -> 0.09911339 | D11: =(VLOOKUP(D$3,'Composite Returns'!$A$578:$K740,11,0)/VLOOKUP(D$2,'Composite Returns'!$A$578:$K740,11,0))-1 -> 0.12012148 | E11: =(VLOOKUP(E$3,'Composite Returns'!$A$578:$K740,11,0)/VLOOKUP(E$2,'Composite Returns'!$A$578:$K740,11,0))^(1/E$4)-1 -> 0.095968502 | F11: =(VLOOKUP(F$3,'Composite Returns'!$A$578:$K740,11,0)/VLOOKUP(F$2,'Composite Returns'!$A$578:$K740,11,0))^(1/F$4)-1 -> 0.062097206 | G11: =(VLOOKUP(G$3,'Composite Returns'!$A$578:$K740,11,0)/VLOOKUP(G$2,'Composite Returns'!$A$578:$K740,11,0))^(1/G$4)-1 -> 0.073546338 | H11: =(VLOOKUP(B$3,'Composite Returns'!$A$578:$K740,11,0)/VLOOKUP(K11,'Composite Returns'!$A$578:$K740,11,0))-1 -> 2.478539 | I11: =(1+H11)^(1/J11)-1 -> 0.079722478 | J11: =+(B$3-K11)/365.242 -> 16.252238 | K11: 40359
A12: Income | B12: =(VLOOKUP(B$3,'Composite Returns'!$A$744:$K905,11,0)/VLOOKUP(B$2,'Composite Returns'!$A$744:$K905,11,0))-1 -> -0.0007153065 | C12: =(VLOOKUP(C$3,'Composite Returns'!$A$744:$K905,11,0)/VLOOKUP(C$2,'Composite Returns'!$A$744:$K905,11,0))-1 -> 0.011324941 | D12: =(VLOOKUP(D$3,'Composite Returns'!$A$744:$K905,11,0)/VLOOKUP(D$2,'Composite Returns'!$A$744:$K905,11,0))-1 -> 0.019741855 | E12: =(VLOOKUP(E$3,'Composite Returns'!$A$744:$K905,11,0)/VLOOKUP(E$2,'Composite Returns'!$A$744:$K905,11,0))^(1/E$4)-1 -> 0.042737078 | F12: =(VLOOKUP(F$3,'Composite Returns'!$A$744:$K905,11,0)/VLOOKUP(F$2,'Composite Returns'!$A$744:$K905,11,0))^(1/F$4)-1 -> 0.016887781 | G12: =(VLOOKUP(G$3,'Composite Returns'!$A$744:$K905,11,0)/VLOOKUP(G$2,'Composite Returns'!$A$744:$K905,11,0))^(1/G$4)-1 -> 0.018705196 | H12: =(VLOOKUP(B$3,'Composite Returns'!$A$744:$K905,11,0)/VLOOKUP(K12,'Composite Returns'!$A$744:$K905,11,0))-1 -> 0.34625642 | I12: =(1+H12)^(1/J12)-1 -> 0.018756306 | J12: =+(B$3-K12)/365.242 -> 16.00035 | K12: 40451
A13: S&P 500 High Dividend | B13: =(VLOOKUP(B$3,'Composite Returns'!$A$5:$S167,19,0)/VLOOKUP(B$2,'Composite Returns'!$A$5:$S167,19,0))-1 -> -0.038738995 | C13: =(VLOOKUP(C$3,'Composite Returns'!$A$5:$S167,19,0)/VLOOKUP(C$2,'Composite Returns'!$A$5:$S167,19,0))-1 -> 0.084538959 | D13: =(VLOOKUP(D$3,'Composite Returns'!$A$5:$S167,19,0)/VLOOKUP(D$2,'Composite Returns'!$A$5:$S167,19,0))-1 -> 0.079212861 | E13: =(VLOOKUP(E$3,'Composite Returns'!$A$5:$S167,19,0)/VLOOKUP(E$2,'Composite Returns'!$A$5:$S167,19,0))^(1/E$4)-1 -> 0.14054113 | F13: =(VLOOKUP(F$3,'Composite Returns'!$A$5:$S167,19,0)/VLOOKUP(F$2,'Composite Returns'!$A$5:$S167,19,0))^(1/F$4)-1 -> 0.077344675 | G13: =(VLOOKUP(G$3,'Composite Returns'!$A$5:$S167,19,0)/VLOOKUP(G$2,'Composite Returns'!$A$5:$S167,19,0))^(1/G$4)-1 -> 0.078381862 | H13: =(VLOOKUP(B$3,'Composite Returns'!$A$5:$S167,19,0)/VLOOKUP(K13,'Composite Returns'!$A$5:$S167,19,0))-1 -> 4.8569474 | I13: =(1+H13)^(1/J13)-1 -> 0.11489715 | J13: =+(B$3-K13)/365.242 -> 16.252238 | K13: 40359
A14: S&P 500 | B14: =(VLOOKUP(B$3,'Composite Returns'!$A$5:$O167,15,0)/VLOOKUP(B$2,'Composite Returns'!$A$5:$O167,15,0))-1 -> 0.022990637 | C14: =(VLOOKUP(C$3,'Composite Returns'!$A$5:$O167,15,0)/VLOOKUP(C$2,'Composite Returns'!$A$5:$O167,15,0))-1 -> 0.12736958 | D14: =(VLOOKUP(D$3,'Composite Returns'!$A$5:$O167,15,0)/VLOOKUP(D$2,'Composite Returns'!$A$5:$O167,15,0))-1 -> 0.15732838 | E14: =(VLOOKUP(E$3,'Composite Returns'!$A$5:$O167,15,0)/VLOOKUP(E$2,'Composite Returns'!$A$5:$O167,15,0))^(1/E$4)-1 -> 0.22895566 | F14: =(VLOOKUP(F$3,'Composite Returns'!$A$5:$O167,15,0)/VLOOKUP(F$2,'Composite Returns'!$A$5:$O167,15,0))^(1/F$4)-1 -> 0.13795908 | G14: =(VLOOKUP(G$3,'Composite Returns'!$A$5:$O167,15,0)/VLOOKUP(G$2,'Composite Returns'!$A$5:$O167,15,0))^(1/G$4)-1 -> 0.1533948 | H14: =(VLOOKUP(B$3,'Composite Returns'!$A$5:$O167,15,0)/VLOOKUP(K14,'Composite Returns'!$A$5:$O167,15,0))-1 -> 9.0108325 | I14: =(1+H14)^(1/J14)-1 -> 0.15228237 | J14: =+(B$3-K14)/365.242 -> 16.252238 | K14: 40359
A15: S&P 400 Aristocrats | B15: =(VLOOKUP(B$3,'Composite Returns'!$A$171:$S313,19,0)/VLOOKUP(B$2,'Composite Returns'!$A$171:$S313,19,0))-1 -> -0.050190198 | C15: =(VLOOKUP(C$3,'Composite Returns'!$A$171:$S313,19,0)/VLOOKUP(C$2,'Composite Returns'!$A$171:$S313,19,0))-1 -> 0.046019346 | D15: =(VLOOKUP(D$3,'Composite Returns'!$A$171:$S313,19,0)/VLOOKUP(D$2,'Composite Returns'!$A$171:$S313,19,0))-1 -> 0.041223061 | E15: =(VLOOKUP(E$3,'Composite Returns'!$A$171:$S313,19,0)/VLOOKUP(E$2,'Composite Returns'!$A$171:$S313,19,0))^(1/E$4)-1 -> 0.12130797 | F15: =(VLOOKUP(F$3,'Composite Returns'!$A$171:$S313,19,0)/VLOOKUP(F$2,'Composite Returns'!$A$171:$S313,19,0))^(1/F$4)-1 -> 0.080064117 | G15: =(VLOOKUP(G$3,'Composite Returns'!$A$171:$S313,19,0)/VLOOKUP(G$2,'Composite Returns'!$A$171:$S313,19,0))^(1/G$4)-1 -> 0.093179027 | H15: =(VLOOKUP(B$3,'Composite Returns'!$A$171:$S313,19,0)/VLOOKUP(K15,'Composite Returns'!$A$171:$S313,19,0))-1 -> 1.9279317 | I15: =(1+H15)^(1/J15)-1 -> 0.095753347 | J15: =+(B$3-K15)/365.242 -> 11.748375 | K15: 42004
A16: S&P Mid Cap 400 | B16: =(VLOOKUP(B$3,'Composite Returns'!$A$171:$O313,15,0)/VLOOKUP(B$2,'Composite Returns'!$A$171:$O313,15,0))-1 -> -0.063593133 | C16: =(VLOOKUP(C$3,'Composite Returns'!$A$171:$O313,15,0)/VLOOKUP(C$2,'Composite Returns'!$A$171:$O313,15,0))-1 -> 0.098672079 | D16: =(VLOOKUP(D$3,'Composite Returns'!$A$171:$O313,15,0)/VLOOKUP(D$2,'Composite Returns'!$A$171:$O313,15,0))-1 -> 0.11670639 | E16: =(VLOOKUP(E$3,'Composite Returns'!$A$171:$O313,15,0)/VLOOKUP(E$2,'Composite Returns'!$A$171:$O313,15,0))^(1/E$4)-1 -> 0.14544738 | F16: =(VLOOKUP(F$3,'Composite Returns'!$A$171:$O313,15,0)/VLOOKUP(F$2,'Composite Returns'!$A$171:$O313,15,0))^(1/F$4)-1 -> 0.080313853 | G16: =(VLOOKUP(G$3,'Composite Returns'!$A$171:$O313,15,0)/VLOOKUP(G$2,'Composite Returns'!$A$171:$O313,15,0))^(1/G$4)-1 -> 0.10468997 | H16: =(VLOOKUP(B$3,'Composite Returns'!$A$171:$O313,15,0)/VLOOKUP(K16,'Composite Returns'!$A$171:$O313,15,0))-1 -> 1.975829 | I16: =(1+H16)^(1/J16)-1 -> 0.097267804 | J16: =+(B$3-K16)/365.242 -> 11.748375 | K16: 42004
A17: Dow Jones Select Dvd | B17: =(VLOOKUP(B$3,'Composite Returns'!$A$317:$S447,19,0)/VLOOKUP(B$2,'Composite Returns'!$A$317:$S447,19,0))-1 -> -0.018317059 | C17: =(VLOOKUP(C$3,'Composite Returns'!$A$317:$S447,19,0)/VLOOKUP(C$2,'Composite Returns'!$A$317:$S447,19,0))-1 -> 0.10613537 | D17: =(VLOOKUP(D$3,'Composite Returns'!$A$317:$S447,19,0)/VLOOKUP(D$2,'Composite Returns'!$A$317:$S447,19,0))-1 -> 0.11231874 | E17: =(VLOOKUP(E$3,'Composite Returns'!$A$317:$S447,19,0)/VLOOKUP(E$2,'Composite Returns'!$A$317:$S447,19,0))^(1/E$4)-1 -> 0.16798688 | F17: =(VLOOKUP(F$3,'Composite Returns'!$A$317:$S447,19,0)/VLOOKUP(F$2,'Composite Returns'!$A$317:$S447,19,0))^(1/F$4)-1 -> 0.10112685 | G17: =(VLOOKUP(G$3,'Composite Returns'!$A$317:$S447,19,0)/VLOOKUP(G$2,'Composite Returns'!$A$317:$S447,19,0))^(1/G$4)-1 -> 0.1019165 | H17: =(VLOOKUP(B$3,'Composite Returns'!$A$317:$S447,19,0)/VLOOKUP(K17,'Composite Returns'!$A$317:$S447,19,0))-1 -> 2.0913921 | I17: =(1+H17)^(1/J17)-1 -> 0.11070778 | J17: =+(B$3-K17)/365.242 -> 10.749038 | K17: 42369
A18: Russell 3000 | B18: =(VLOOKUP(B$3,'Composite Returns'!$A$317:$O447,15,0)/VLOOKUP(B$2,'Composite Returns'!$A$317:$O447,15,0))-1 -> 0.013981622 | C18: =(VLOOKUP(C$3,'Composite Returns'!$A$317:$O447,15,0)/VLOOKUP(C$2,'Composite Returns'!$A$317:$O447,15,0))-1 -> 0.12450967 | D18: =(VLOOKUP(D$3,'Composite Returns'!$A$317:$O447,15,0)/VLOOKUP(D$2,'Composite Returns'!$A$317:$O447,15,0))-1 -> 0.15167257 | E18: =(VLOOKUP(E$3,'Composite Returns'!$A$317:$O447,15,0)/VLOOKUP(E$2,'Composite Returns'!$A$317:$O447,15,0))^(1/E$4)-1 -> 0.22274811 | F18: =(VLOOKUP(F$3,'Composite Returns'!$A$317:$O447,15,0)/VLOOKUP(F$2,'Composite Returns'!$A$317:$O447,15,0))^(1/F$4)-1 -> 0.12657419 | G18: =(VLOOKUP(G$3,'Composite Returns'!$A$317:$O447,15,0)/VLOOKUP(G$2,'Composite Returns'!$A$317:$O447,15,0))^(1/G$4)-1 -> 0.1473258 | H18: =(VLOOKUP(B$3,'Composite Returns'!$A$317:$O447,15,0)/VLOOKUP(K18,'Composite Returns'!$A$317:$O447,15,0))-1 -> 3.2762052 | I18: =(1+H18)^(1/J18)-1 -> 0.144744 | J18: =+(B$3-K18)/365.242 -> 10.749038 | K18: 42369
A19: Barclay's Agg. Bond | B19: =(VLOOKUP(B$3,'Composite Returns'!$A$744:$O905,15,0)/VLOOKUP(B$2,'Composite Returns'!$A$744:$O905,15,0))-1 -> -0.035011867 | C19: =(VLOOKUP(C$3,'Composite Returns'!$A$744:$O905,15,0)/VLOOKUP(C$2,'Composite Returns'!$A$744:$O905,15,0))-1 -> -0.029009023 | D19: =(VLOOKUP(D$3,'Composite Returns'!$A$744:$O905,15,0)/VLOOKUP(D$2,'Composite Returns'!$A$744:$O905,15,0))-1 -> -0.018406013 | E19: =(VLOOKUP(E$3,'Composite Returns'!$A$744:$O905,15,0)/VLOOKUP(E$2,'Composite Returns'!$A$744:$O905,15,0))^(1/E$4)-1 -> 0.040645155 | F19: =(VLOOKUP(F$3,'Composite Returns'!$A$744:$O905,15,0)/VLOOKUP(F$2,'Composite Returns'!$A$744:$O905,15,0))^(1/F$4)-1 -> -0.0063863345 | G19: =(VLOOKUP(G$3,'Composite Returns'!$A$744:$O905,15,0)/VLOOKUP(G$2,'Composite Returns'!$A$744:$O905,15,0))^(1/G$4)-1 -> 0.011364522 | H19: =(VLOOKUP(B$3,'Composite Returns'!$A$744:$O905,15,0)/VLOOKUP(K19,'Composite Returns'!$A$744:$O905,15,0))-1 -> 0.34351088 | I19: =(1+H19)^(1/J19)-1 -> 0.018626332 | J19: =+(B$3-K19)/365.242 -> 16.00035 | K19: 40451
A20: Balanced Benchmark** | B20: =(VLOOKUP(B$3,'Composite Returns'!$A$578:$O740,15,0)/VLOOKUP(B$2,'Composite Returns'!$A$578:$O740,15,0))-1 -> -0.00035221937 | C20: =(VLOOKUP(C$3,'Composite Returns'!$A$578:$O740,15,0)/VLOOKUP(C$2,'Composite Returns'!$A$578:$O740,15,0))-1 -> 0.063340488 | D20: =(VLOOKUP(D$3,'Composite Returns'!$A$578:$O740,15,0)/VLOOKUP(D$2,'Composite Returns'!$A$578:$O740,15,0))-1 -> 0.085528519 | E20: =(VLOOKUP(E$3,'Composite Returns'!$A$578:$O740,15,0)/VLOOKUP(E$2,'Composite Returns'!$A$578:$O740,15,0))^(1/E$4)-1 -> 0.15166917 | F20: =(VLOOKUP(F$3,'Composite Returns'!$A$578:$O740,15,0)/VLOOKUP(F$2,'Composite Returns'!$A$578:$O740,15,0))^(1/F$4)-1 -> 0.080081789 | G20: =(VLOOKUP(G$3,'Composite Returns'!$A$578:$O740,15,0)/VLOOKUP(G$2,'Composite Returns'!$A$578:$O740,15,0))^(1/G$4)-1 -> 0.09710389 | H20: =(VLOOKUP(B$3,'Composite Returns'!$A$578:$O740,15,0)/VLOOKUP(K20,'Composite Returns'!$A$578:$O740,15,0))-1 -> 3.7439827 | I20: =(1+H20)^(1/J20)-1 -> 0.10053302 | J20: =+(B$3-K20)/365.242 -> 16.252238 | K20: 40359
A22: *Composite performance presented based on the composite of actual client account performance gross of management fees. Martin Capital Partners, LLC was formed in June of 2010, and inception of strategy performance aggregation began June 30, 2010. The Income Composite's inception date is September 30,2010, as is Barclay's Agg Bond index. The Dividend Opportunity Composite's inception date is 12/31/2014, as is the S&P Mid Cap 400 index.. The Dividend All-Cap Composite's inception date is 12/31/2015. The Oregon Composite's inception date is 9/30/2017. Past performance provides no indication of future results.
A23: **Blended return using 60% S&P 500 and 40% Barclay's Aggregate Bond indices as and average benchmark
A30: Composite Performance - Annual Returns
A31: Calendar Year | B31: Quality Dividend Strategy | C31: Quality SMID Dividend Strategy | D31: Quality All-Cap Dividend Strategy | E31: Oregon Dividend Strategy | F31: S&P 500 | G31: S&P 500 High Dividend | H31: S&P 400 | I31: Russell 3000 | M31: 46022
A32: 2025 | B32: =(VLOOKUP(M$31,'Composite Returns'!$A$5:$K167,11,0)/VLOOKUP(M$32,'Composite Returns'!$A$5:$K167,11,0))-1 -> 0.065920397 | C32: =(VLOOKUP(M$31,'Composite Returns'!$A$171:$K313,11,0)/VLOOKUP(M$32,'Composite Returns'!$A$171:$K313,11,0))-1 -> 0.04359011 | D32: =(VLOOKUP(M$31,'Composite Returns'!$A$317:$K447,11,0)/VLOOKUP(M$32,'Composite Returns'!$A$317:$K447,11,0))-1 -> 0.069147968 | E32: =(VLOOKUP(M$31,'Composite Returns'!$A$451:$K560,11,0)/VLOOKUP(M$32,'Composite Returns'!$A$451:$K560,11,0))-1 -> 0.030877656 | F32: =(VLOOKUP(M$31,'Composite Returns'!$A$5:$O167,15,0)/VLOOKUP(M$32,'Composite Returns'!$A$5:$O167,15,0))-1 -> 0.17885003 | G32: =(VLOOKUP(M$31,'Composite Returns'!$A$5:$S167,19,0)/VLOOKUP(M$32,'Composite Returns'!$A$5:$S167,19,0))-1 -> 0.046763258 | H32: =(VLOOKUP(M$31,'Composite Returns'!$A$171:$O313,15,0)/VLOOKUP(M$32,'Composite Returns'!$A$171:$O313,15,0))-1 -> 0.075019221 | I32: =(VLOOKUP(M$31,'Composite Returns'!$A$317:$O447,15,0)/VLOOKUP(M$32,'Composite Returns'!$A$317:$O447,15,0))-1 -> 0.17168068 | M32: 45657
A33: 2024 | B33: =(VLOOKUP(M$32,'Composite Returns'!$A$5:$K167,11,0)/VLOOKUP(M$33,'Composite Returns'!$A$5:$K167,11,0))-1 -> 0.063250471 | C33: =(VLOOKUP(M$32,'Composite Returns'!$A$171:$K313,11,0)/VLOOKUP(M$33,'Composite Returns'!$A$171:$K313,11,0))-1 -> 0.081255972 | D33: =(VLOOKUP(M$32,'Composite Returns'!$A$317:$K447,11,0)/VLOOKUP(M$33,'Composite Returns'!$A$317:$K447,11,0))-1 -> 0.065327051 | E33: =(VLOOKUP(M$32,'Composite Returns'!$A$451:$K560,11,0)/VLOOKUP(M$33,'Composite Returns'!$A$451:$K560,11,0))-1 -> 0.080180165 | F33: =(VLOOKUP(M$32,'Composite Returns'!$A$5:$O167,15,0)/VLOOKUP(M$33,'Composite Returns'!$A$5:$O167,15,0))-1 -> 0.25047334 | G33: =(VLOOKUP(M$32,'Composite Returns'!$A$5:$S167,19,0)/VLOOKUP(M$33,'Composite Returns'!$A$5:$S167,19,0))-1 -> 0.15291355 | H33: =(VLOOKUP(M$32,'Composite Returns'!$A$171:$O313,15,0)/VLOOKUP(M$33,'Composite Returns'!$A$171:$O313,15,0))-1 -> 0.13945036 | I33: =(VLOOKUP(M$32,'Composite Returns'!$A$317:$O447,15,0)/VLOOKUP(M$33,'Composite Returns'!$A$317:$O447,15,0))-1 -> 0.23815379 | M33: 45291
A34: 2023 | B34: =(VLOOKUP(M$33,'Composite Returns'!$A$5:$K167,11,0)/VLOOKUP(M$34,'Composite Returns'!$A$5:$K167,11,0))-1 -> 0.042134503 | C34: =(VLOOKUP(M$33,'Composite Returns'!$A$171:$K313,11,0)/VLOOKUP(M$34,'Composite Returns'!$A$171:$K313,11,0))-1 -> 0.078745723 | D34: =(VLOOKUP(M$33,'Composite Returns'!$A$317:$K447,11,0)/VLOOKUP(M$34,'Composite Returns'!$A$317:$K447,11,0))-1 -> 0.051222115 | E34: =(VLOOKUP(M$33,'Composite Returns'!$A$451:$K560,11,0)/VLOOKUP(M$34,'Composite Returns'!$A$451:$K560,11,0))-1 -> 0.080760948 | F34: =(VLOOKUP(M$33,'Composite Returns'!$A$5:$O167,15,0)/VLOOKUP(M$34,'Composite Returns'!$A$5:$O167,15,0))-1 -> 0.26271306 | G34: =(VLOOKUP(M$33,'Composite Returns'!$A$5:$S167,19,0)/VLOOKUP(M$34,'Composite Returns'!$A$5:$S167,19,0))-1 -> 0.039065471 | H34: =(VLOOKUP(M$33,'Composite Returns'!$A$171:$O313,15,0)/VLOOKUP(M$34,'Composite Returns'!$A$171:$O313,15,0))-1 -> 0.16450555 | I34: =(VLOOKUP(M$33,'Composite Returns'!$A$317:$O447,15,0)/VLOOKUP(M$34,'Composite Returns'!$A$317:$O447,15,0))-1 -> 0.25974589 | M34: 44926
A35: 2022 | B35: =(VLOOKUP(M$34,'Composite Returns'!$A$5:$K167,11,0)/VLOOKUP(M$35,'Composite Returns'!$A$5:$K167,11,0))-1 -> 0.018062325 | C35: =(VLOOKUP(M$34,'Composite Returns'!$A$171:$K313,11,0)/VLOOKUP(M$35,'Composite Returns'!$A$171:$K313,11,0))-1 -> -0.04740881 | D35: =(VLOOKUP(M$34,'Composite Returns'!$A$317:$K447,11,0)/VLOOKUP(M$35,'Composite Returns'!$A$317:$K447,11,0))-1 -> -0.01239914 | E35: =(VLOOKUP(M$34,'Composite Returns'!$A$451:$K560,11,0)/VLOOKUP(M$35,'Composite Returns'!$A$451:$K560,11,0))-1 -> -0.064008363 | F35: =(VLOOKUP(M$34,'Composite Returns'!$A$5:$O167,15,0)/VLOOKUP(M$35,'Composite Returns'!$A$5:$O167,15,0))-1 -> -0.18100973 | G35: =(VLOOKUP(M$34,'Composite Returns'!$A$5:$S167,19,0)/VLOOKUP(M$35,'Composite Returns'!$A$5:$S167,19,0))-1 -> -0.011068909 | H35: =(VLOOKUP(M$34,'Composite Returns'!$A$171:$O313,15,0)/VLOOKUP(M$35,'Composite Returns'!$A$171:$O313,15,0))-1 -> -0.13061301 | I35: =(VLOOKUP(M$34,'Composite Returns'!$A$317:$O447,15,0)/VLOOKUP(M$35,'Composite Returns'!$A$317:$O447,15,0))-1 -> -0.19196595 | M35: 44561
A36: 2021 | B36: =(VLOOKUP(M$35,'Composite Returns'!$A$5:$K167,11,0)/VLOOKUP(M$36,'Composite Returns'!$A$5:$K167,11,0))-1 -> 0.19521029 | C36: =(VLOOKUP(M$35,'Composite Returns'!$A$171:$K313,11,0)/VLOOKUP(M$36,'Composite Returns'!$A$171:$K313,11,0))-1 -> 0.253714 | D36: =(VLOOKUP(M$35,'Composite Returns'!$A$317:$K447,11,0)/VLOOKUP(M$36,'Composite Returns'!$A$317:$K447,11,0))-1 -> 0.22438591 | E36: =(VLOOKUP(M$35,'Composite Returns'!$A$451:$K560,11,0)/VLOOKUP(M$36,'Composite Returns'!$A$451:$K560,11,0))-1 -> 0.2384833 | F36: =(VLOOKUP(M$35,'Composite Returns'!$A$5:$O167,15,0)/VLOOKUP(M$36,'Composite Returns'!$A$5:$O167,15,0))-1 -> 0.2872137 | G36: =(VLOOKUP(M$35,'Composite Returns'!$A$5:$S167,19,0)/VLOOKUP(M$36,'Composite Returns'!$A$5:$S167,19,0))-1 -> 0.32853144 | H36: =(VLOOKUP(M$35,'Composite Returns'!$A$171:$O313,15,0)/VLOOKUP(M$36,'Composite Returns'!$A$171:$O313,15,0))-1 -> 0.24772195 | I36: =(VLOOKUP(M$35,'Composite Returns'!$A$317:$O447,15,0)/VLOOKUP(M$36,'Composite Returns'!$A$317:$O447,15,0))-1 -> 0.25640625 | M36: 44196
A37: 2020 | B37: =(VLOOKUP(M$36,'Composite Returns'!$A$5:$K167,11,0)/VLOOKUP(M$37,'Composite Returns'!$A$5:$K167,11,0))-1 -> 0.032004648 | C37: =(VLOOKUP(M$36,'Composite Returns'!$A$171:$K313,11,0)/VLOOKUP(M$37,'Composite Returns'!$A$171:$K313,11,0))-1 -> 0.03677544 | D37: =(VLOOKUP(M$36,'Composite Returns'!$A$317:$K447,11,0)/VLOOKUP(M$37,'Composite Returns'!$A$317:$K447,11,0))-1 -> 0.068617832 | E37: =(VLOOKUP(M$36,'Composite Returns'!$A$451:$K560,11,0)/VLOOKUP(M$37,'Composite Returns'!$A$451:$K560,11,0))-1 -> 0.085093726 | F37: =(VLOOKUP(M$36,'Composite Returns'!$A$5:$O167,15,0)/VLOOKUP(M$37,'Composite Returns'!$A$5:$O167,15,0))-1 -> 0.18402028 | G37: =(VLOOKUP(M$36,'Composite Returns'!$A$5:$S167,19,0)/VLOOKUP(M$37,'Composite Returns'!$A$5:$S167,19,0))-1 -> -0.1158748 | H37: =(VLOOKUP(M$36,'Composite Returns'!$A$171:$O313,15,0)/VLOOKUP(M$37,'Composite Returns'!$A$171:$O313,15,0))-1 -> 0.1364257 | I37: =(VLOOKUP(M$36,'Composite Returns'!$A$317:$O447,15,0)/VLOOKUP(M$37,'Composite Returns'!$A$317:$O447,15,0))-1 -> 0.20891653 | M37: 43830
A38: 2019 | B38: =(VLOOKUP(M$37,'Composite Returns'!$A$5:$K167,11,0)/VLOOKUP(M$38,'Composite Returns'!$A$5:$K167,11,0))-1 -> 0.24388608 | C38: =(VLOOKUP(M$37,'Composite Returns'!$A$171:$K313,11,0)/VLOOKUP(M$38,'Composite Returns'!$A$171:$K313,11,0))-1 -> 0.17277636 | D38: =(VLOOKUP(M$37,'Composite Returns'!$A$317:$K447,11,0)/VLOOKUP(M$38,'Composite Returns'!$A$317:$K447,11,0))-1 -> 0.23129384 | E38: =(VLOOKUP(M$37,'Composite Returns'!$A$451:$K560,11,0)/VLOOKUP(M$38,'Composite Returns'!$A$451:$K560,11,0))-1 -> 0.25549985 | F38: =(VLOOKUP(M$37,'Composite Returns'!$A$5:$O167,15,0)/VLOOKUP(M$38,'Composite Returns'!$A$5:$O167,15,0))-1 -> 0.3150318 | G38: =(VLOOKUP(M$37,'Composite Returns'!$A$5:$S167,19,0)/VLOOKUP(M$38,'Composite Returns'!$A$5:$S167,19,0))-1 -> 0.21488502 | H38: =(VLOOKUP(M$37,'Composite Returns'!$A$171:$O313,15,0)/VLOOKUP(M$38,'Composite Returns'!$A$171:$O313,15,0))-1 -> 0.26207066 | I38: =(VLOOKUP(M$37,'Composite Returns'!$A$317:$O447,15,0)/VLOOKUP(M$38,'Composite Returns'!$A$317:$O447,15,0))-1 -> 0.31019047 | M38: 43465
A39: 2018 | B39: =(VLOOKUP(M$38,'Composite Returns'!$A$5:$K167,11,0)/VLOOKUP(M$39,'Composite Returns'!$A$5:$K167,11,0))-1 -> 0.0049030845 | C39: =(VLOOKUP(M$38,'Composite Returns'!$A$171:$K313,11,0)/VLOOKUP(M$39,'Composite Returns'!$A$171:$K313,11,0))-1 -> -0.055655385 | D39: =(VLOOKUP(M$38,'Composite Returns'!$A$317:$K447,11,0)/VLOOKUP(M$39,'Composite Returns'!$A$317:$K447,11,0))-1 -> 0.0083228383 | E39: =(VLOOKUP(M$38,'Composite Returns'!$A$451:$K560,11,0)/VLOOKUP(M$39,'Composite Returns'!$A$451:$K560,11,0))-1 -> -0.021705108 | F39: =(VLOOKUP(M$38,'Composite Returns'!$A$5:$O167,15,0)/VLOOKUP(M$39,'Composite Returns'!$A$5:$O167,15,0))-1 -> -0.043838845 | G39: =(VLOOKUP(M$38,'Composite Returns'!$A$5:$S167,19,0)/VLOOKUP(M$39,'Composite Returns'!$A$5:$S167,19,0))-1 -> -0.047542037 | H39: =(VLOOKUP(M$38,'Composite Returns'!$A$171:$O313,15,0)/VLOOKUP(M$39,'Composite Returns'!$A$171:$O313,15,0))-1 -> -0.11103592 | I39: =(VLOOKUP(M$38,'Composite Returns'!$A$317:$O447,15,0)/VLOOKUP(M$39,'Composite Returns'!$A$317:$O447,15,0))-1 -> -0.052454647 | M39: 43100 | N39: 43008
A40: 2017 | B40: =(VLOOKUP(M$39,'Composite Returns'!$A$5:$K167,11,0)/VLOOKUP(M$40,'Composite Returns'!$A$5:$K167,11,0))-1 -> 0.16957768 | C40: =(VLOOKUP(M$39,'Composite Returns'!$A$171:$K313,11,0)/VLOOKUP(M$40,'Composite Returns'!$A$171:$K313,11,0))-1 -> 0.14498798 | D40: =(VLOOKUP(M$39,'Composite Returns'!$A$317:$K447,11,0)/VLOOKUP(M$40,'Composite Returns'!$A$317:$K447,11,0))-1 -> 0.16990253 | E40: =(VLOOKUP(M$39,'Composite Returns'!$A$451:$K560,11,0)/VLOOKUP(N$39,'Composite Returns'!$A$451:$K560,11,0))-1 -> 0.061861396 | F40: =(VLOOKUP(M$39,'Composite Returns'!$A$5:$O167,15,0)/VLOOKUP(M$40,'Composite Returns'!$A$5:$O167,15,0))-1 -> 0.21843744 | G40: =(VLOOKUP(M$39,'Composite Returns'!$A$5:$S167,19,0)/VLOOKUP(M$40,'Composite Returns'!$A$5:$S167,19,0))-1 -> 0.12760393 | H40: =(VLOOKUP(M$39,'Composite Returns'!$A$171:$O313,15,0)/VLOOKUP(M$40,'Composite Returns'!$A$171:$O313,15,0))-1 -> 0.16243442 | I40: =(VLOOKUP(M$39,'Composite Returns'!$A$317:$O447,15,0)/VLOOKUP(M$40,'Composite Returns'!$A$317:$O447,15,0))-1 -> 0.21130023 | M40: 42735
A41: 2016 | B41: =(VLOOKUP(M$40,'Composite Returns'!$A$5:$K167,11,0)/VLOOKUP(M$41,'Composite Returns'!$A$5:$K167,11,0))-1 -> 0.10542536 | C41: =(VLOOKUP(M$40,'Composite Returns'!$A$171:$K313,11,0)/VLOOKUP(M$41,'Composite Returns'!$A$171:$K313,11,0))-1 -> 0.24275376 | D41: =(VLOOKUP(M$40,'Composite Returns'!$A$317:$K447,11,0)/VLOOKUP(M$41,'Composite Returns'!$A$317:$K447,11,0))-1 -> 0.15752349 | F41: =(VLOOKUP(M$40,'Composite Returns'!$A$5:$O167,15,0)/VLOOKUP(M$41,'Composite Returns'!$A$5:$O167,15,0))-1 -> 0.11981281 | G41: =(VLOOKUP(M$40,'Composite Returns'!$A$5:$S167,19,0)/VLOOKUP(M$41,'Composite Returns'!$A$5:$S167,19,0))-1 -> 0.24980456 | H41: =(VLOOKUP(M$40,'Composite Returns'!$A$171:$O313,15,0)/VLOOKUP(M$41,'Composite Returns'!$A$171:$O313,15,0))-1 -> 0.20739042 | I41: =(VLOOKUP(M$40,'Composite Returns'!$A$317:$O447,15,0)/VLOOKUP(M$41,'Composite Returns'!$A$317:$O447,15,0))-1 -> 0.12742127 | M41: 42369
A42: 2015 | B42: =(VLOOKUP(M$41,'Composite Returns'!$A$5:$K167,11,0)/VLOOKUP(M$42,'Composite Returns'!$A$5:$K167,11,0))-1 -> -0.018554452 | C42: =(VLOOKUP(M$41,'Composite Returns'!$A$171:$K313,11,0)/VLOOKUP(M$42,'Composite Returns'!$A$171:$K313,11,0))-1 -> 0.0010227484 | F42: =(VLOOKUP(M$41,'Composite Returns'!$A$5:$O167,15,0)/VLOOKUP(M$42,'Composite Returns'!$A$5:$O167,15,0))-1 -> 0.013976128 | G42: =(VLOOKUP(M$41,'Composite Returns'!$A$5:$S167,19,0)/VLOOKUP(M$42,'Composite Returns'!$A$5:$S167,19,0))-1 -> -0.023962706 | H42: =(VLOOKUP(M$41,'Composite Returns'!$A$171:$O313,15,0)/VLOOKUP(M$42,'Composite Returns'!$A$171:$O313,15,0))-1 -> -0.021793331 | M42: 42004
A43: 2014 | B43: =(VLOOKUP(M$42,'Composite Returns'!$A$5:$K167,11,0)/VLOOKUP(M$43,'Composite Returns'!$A$5:$K167,11,0))-1 -> 0.091439946 | F43: =(VLOOKUP(M$42,'Composite Returns'!$A$5:$O167,15,0)/VLOOKUP(M$43,'Composite Returns'!$A$5:$O167,15,0))-1 -> 0.13689211 | G43: =(VLOOKUP(M$42,'Composite Returns'!$A$5:$S167,19,0)/VLOOKUP(M$43,'Composite Returns'!$A$5:$S167,19,0))-1 -> 0.2217235 | M43: 41639
A44: 2013 | B44: =(VLOOKUP(M$43,'Composite Returns'!$A$5:$K167,11,0)/VLOOKUP(M$44,'Composite Returns'!$A$5:$K167,11,0))-1 -> 0.21095095 | F44: =(VLOOKUP(M$43,'Composite Returns'!$A$5:$O167,15,0)/VLOOKUP(M$44,'Composite Returns'!$A$5:$O167,15,0))-1 -> 0.32383662 | G44: =(VLOOKUP(M$43,'Composite Returns'!$A$5:$S167,19,0)/VLOOKUP(M$44,'Composite Returns'!$A$5:$S167,19,0))-1 -> 0.28066969 | M44: 41274
A45: 2012 | B45: =(VLOOKUP(M$44,'Composite Returns'!$A$5:$K167,11,0)/VLOOKUP(M$45,'Composite Returns'!$A$5:$K167,11,0))-1 -> 0.087174237 | F45: =(VLOOKUP(M$44,'Composite Returns'!$A$5:$O167,15,0)/VLOOKUP(M$45,'Composite Returns'!$A$5:$O167,15,0))-1 -> 0.15993829 | G45: =(VLOOKUP(M$44,'Composite Returns'!$A$5:$S167,19,0)/VLOOKUP(M$45,'Composite Returns'!$A$5:$S167,19,0))-1 -> 0.10281889 | M45: 40908
A46: 2011 | B46: =(VLOOKUP(M$45,'Composite Returns'!$A$5:$K167,11,0)/VLOOKUP(M$46,'Composite Returns'!$A$5:$K167,11,0))-1 -> 0.11529011 | F46: =(VLOOKUP(M$45,'Composite Returns'!$A$5:$O167,15,0)/VLOOKUP(M$46,'Composite Returns'!$A$5:$O167,15,0))-1 -> 0.020862607 | G46: =(VLOOKUP(M$45,'Composite Returns'!$A$5:$S167,19,0)/VLOOKUP(M$46,'Composite Returns'!$A$5:$S167,19,0))-1 -> 0.12394318 | M46: 40543 | N46: 40359
A47: 2010 | B47: =(VLOOKUP(M$46,'Composite Returns'!$A$5:$K167,11,0)/VLOOKUP(N$46,'Composite Returns'!$A$5:$K167,11,0))-1 -> 0.18964037 | F47: =(VLOOKUP(M$46,'Composite Returns'!$A$5:$O167,15,0)/VLOOKUP(N$46,'Composite Returns'!$A$5:$O167,15,0))-1 -> 0.2327588 | G47: =(VLOOKUP(M$46,'Composite Returns'!$A$5:$S167,19,0)/VLOOKUP(N$46,'Composite Returns'!$A$5:$S167,19,0))-1 -> 0.201107
...

Sheet Old Returns
B1: Core Dividend (Net) | D1: Core Dividend (Gross) | F1: S&P 500
A2: 2010 | B2: =(1+'Composite Returns'!E6)*(1+'Composite Returns'!E7)-1 -> 0.18077722 | D2: =(1+'Composite Returns'!I6)*(1+'Composite Returns'!I7)-1 -> 0.18964037 | F2: =(1+'Composite Returns'!M6)*(1+'Composite Returns'!M7)-1 -> 0.2327588
A3: 2011 | B3: =(1+'Composite Returns'!E8)*(1+'Composite Returns'!E9)*(1+'Composite Returns'!E10)*(1+'Composite Returns'!E11)-1 -> 0.10177898 | D3: =(1+'Composite Returns'!I8)*(1+'Composite Returns'!I9)*(1+'Composite Returns'!I10)*(1+'Composite Returns'!I11)-1 -> 0.11529011 | F3: =(1+'Composite Returns'!M8)*(1+'Composite Returns'!M9)*(1+'Composite Returns'!M10)*(1+'Composite Returns'!M11)-1 -> 0.020862607
A4: 2012 | B4: =(1+'Composite Returns'!E12)*(1+'Composite Returns'!E13)*(1+'Composite Returns'!E14)*(1+'Composite Returns'!E15)-1 -> 0.075546796 | D4: =(1+'Composite Returns'!I12)*(1+'Composite Returns'!I13)*(1+'Composite Returns'!I14)*(1+'Composite Returns'!I15)-1 -> 0.087174237 | F4: =(1+'Composite Returns'!M12)*(1+'Composite Returns'!M13)*(1+'Composite Returns'!M14)*(1+'Composite Returns'!M15)-1 -> 0.15993829
A5: 2013 | B5: =(1+'Composite Returns'!E16)*(1+'Composite Returns'!E17)*(1+'Composite Returns'!E18)*(1+'Composite Returns'!E19)-1 -> 0.19866082 | D5: =(1+'Composite Returns'!I16)*(1+'Composite Returns'!I17)*(1+'Composite Returns'!I18)*(1+'Composite Returns'!I19)-1 -> 0.21095095 | F5: =(1+'Composite Returns'!M16)*(1+'Composite Returns'!M17)*(1+'Composite Returns'!M18)*(1+'Composite Returns'!M19)-1 -> 0.32383662
A6: 2014 | B6: =(1+'Composite Returns'!E20)*(1+'Composite Returns'!E21)*(1+'Composite Returns'!E22)*(1+'Composite Returns'!E23)*(1+'Composite Returns'!E24)*(1+'Composite Returns'!E25)-1 -> 0.08017307 | D6: =(1+'Composite Returns'!I20)*(1+'Composite Returns'!I21)*(1+'Composite Returns'!I22)*(1+'Composite Returns'!I23)*(1+'Composite Returns'!I24)*(1+'Composite Returns'!I25)-1 -> 0.091439946 | F6: =(1+'Composite Returns'!M20)*(1+'Composite Returns'!M21)*(1+'Composite Returns'!M22)*(1+'Composite Returns'!M23)*(1+'Composite Returns'!M24)*(1+'Composite Returns'!M25)-1 -> 0.13689211
A7: 2015 | B7: =(1+'Composite Returns'!E26)*(1+'Composite Returns'!E27)*(1+'Composite Returns'!E28)*(1+'Composite Returns'!E29)*(1+'Composite Returns'!E30)*(1+'Composite Returns'!E31)*(1+'Composite Returns'!E32)*(1+'Composite Returns'!E33)*(1+'Composite Returns'!E34)*(1+'Composite Returns'!E35)*(1+'Composite Returns'!E36)*(1+'Composite Returns'!E37)-1 -> -0.028282902 | D7: =(1+'Composite Returns'!I26)*(1+'Composite Returns'!I27)*(1+'Composite Returns'!I28)*(1+'Composite Returns'!I29)*(1+'Composite Returns'!I30)*(1+'Composite Returns'!I31)*(1+'Composite Returns'!I32)*(1+'Composite Returns'!I33)*(1+'Composite Returns'!I34)*(1+'Composite Returns'!I35)*(1+'Composite Returns'!I36)*(1+'Composite Returns'!I37)-1 -> -0.018554452 | F7: =(1+'Composite Returns'!M26)*(1+'Composite Returns'!M27)*(1+'Composite Returns'!M28)*(1+'Composite Returns'!M29)*(1+'Composite Returns'!M30)*(1+'Composite Returns'!M31)*(1+'Composite Returns'!M32)*(1+'Composite Returns'!M33)*(1+'Composite Returns'!M34)*(1+'Composite Returns'!M35)*(1+'Composite Returns'!M36)*(1+'Composite Returns'!M37)-1 -> 0.013976128
A8: 2016 | B8: =(1+'Composite Returns'!E38)*(1+'Composite Returns'!E39)*(1+'Composite Returns'!E40)*(1+'Composite Returns'!E41)*(1+'Composite Returns'!E42)*(1+'Composite Returns'!E43)*(1+'Composite Returns'!E44)*(1+'Composite Returns'!E45)*(1+'Composite Returns'!E46)*(1+'Composite Returns'!E47)*(1+'Composite Returns'!E48)*(1+'Composite Returns'!E49)-1 -> 0.094701947 | D8: =(1+'Composite Returns'!I38)*(1+'Composite Returns'!I39)*(1+'Composite Returns'!I40)*(1+'Composite Returns'!I41)*(1+'Composite Returns'!I42)*(1+'Composite Returns'!I43)*(1+'Composite Returns'!I44)*(1+'Composite Returns'!I45)*(1+'Composite Returns'!I46)*(1+'Composite Returns'!I47)*(1+'Composite Returns'!I48)*(1+'Composite Returns'!I49)-1 -> 0.10542536 | F8: =(1+'Composite Returns'!M38)*(1+'Composite Returns'!M39)*(1+'Composite Returns'!M40)*(1+'Composite Returns'!M41)*(1+'Composite Returns'!M42)*(1+'Composite Returns'!M43)*(1+'Composite Returns'!M44)*(1+'Composite Returns'!M45)*(1+'Composite Returns'!M46)*(1+'Composite Returns'!M47)*(1+'Composite Returns'!M48)*(1+'Composite Returns'!M49)-1 -> 0.11981281
B12: Div Opp (Net) | D12: Div Opp (Gross) | F12: S&P 400
A13: 2015 | B13: ='Composite Returns'!F183 -> 0.0010227484 | D13: ='Composite Returns'!J183 -> 0.0010227484 | F13: ='Composite Returns'!N183 -> -0.021793331
A14: 2016 | B14: =(1+'Composite Returns'!E184)*(1+'Composite Returns'!E185)*(1+'Composite Returns'!E186)*(1+'Composite Returns'!E187)*(1+'Composite Returns'!E188)*(1+'Composite Returns'!E189)*(1+'Composite Returns'!E190)*(1+'Composite Returns'!E191)*(1+'Composite Returns'!E192)*(1+'Composite Returns'!E193)*(1+'Composite Returns'!E194)*(1+'Composite Returns'!E195)-1 -> 0.23598067 | D14: =(1+'Composite Returns'!I184)*(1+'Composite Returns'!I185)*(1+'Composite Returns'!I186)*(1+'Composite Returns'!I187)*(1+'Composite Returns'!I188)*(1+'Composite Returns'!I189)*(1+'Composite Returns'!I190)*(1+'Composite Returns'!I191)*(1+'Composite Returns'!I192)*(1+'Composite Returns'!I193)*(1+'Composite Returns'!I194)*(1+'Composite Returns'!I195)-1 -> 0.24275376 | F14: =(1+'Composite Returns'!M184)*(1+'Composite Returns'!M185)*(1+'Composite Returns'!M186)*(1+'Composite Returns'!M187)*(1+'Composite Returns'!M188)*(1+'Composite Returns'!M189)*(1+'Composite Returns'!M190)*(1+'Composite Returns'!M191)*(1+'Composite Returns'!M192)*(1+'Composite Returns'!M193)*(1+'Composite Returns'!M194)*(1+'Composite Returns'!M195)-1 -> 0.20739042
A19: Core Flex Composite
A20: Quarter Ending | B20: Ending Value | C20: # of Accounts | E20: Net Composite Return | F20: Cumulative Net Return | I20: Gross Composite Return | J20: Cumulative Gross Return | M20: S&P 500 Return | N20: S&P Cumulative
A21: 40451 | B21: 466441.46 | C21: 2 | E21: 0.1039 | I21: 0.1083 | M21: 0.113
A22: 40543 | B22: 732622.57 | C22: 4 | E22: 0.08346637 | F22: =(E21+1)*(E22+1)-1 -> 0.19603853 | I22: 0.08983888 | J22: =(I21+1)*(I22+1)-1 -> 0.20786843 | M22: 0.1076 | N22: =(M21+1)*(M22+1)-1 -> 0.2327588
A23: 40633 | B23: 764055.69 | C23: 4 | E23: 0.0488 | F23: =(F22+1)*(E23+1)-1 -> 0.25440521 | I23: 0.05607221 | J23: =(J22+1)*(I23+1)-1 -> 0.27559628 | M23: 0.0591 | N23: =(N22+1)*(M23+1)-1 -> 0.30561485
A24: 40724 | B24: 764133.56 | C24: 4 | E24: 0.0001 | F24: =(F23+1)*(E24+1)-1 -> 0.25453065 | I24: 0.00510481 | J24: =(J23+1)*(I24+1)-1 -> 0.28210796 | M24: 0.001 | N24: =(N23+1)*(M24+1)-1 -> 0.30692046
A25: 40816 | B25: 451324.36 | C25: 3 | E25: -0.1316 | F25: =(F24+1)*(E25+1)-1 -> 0.089434413 | I25: -0.12457996 | J25: =(J24+1)*(I25+1)-1 -> 0.122383 | M25: -0.1387 | N25: =(N24+1)*(M25+1)-1 -> 0.12565059
A26: 40908 | B26: 351949.69 | C26: 2 | E26: 0.0921 | F26: =(F25+1)*(E26+1)-1 -> 0.18977132 | I26: 0.0985572 | J26: =(J25+1)*(I26+1)-1 -> 0.23300193 | M26: 0.118 | N26: =(N25+1)*(M26+1)-1 -> 0.25847736
A27: 40999 | B27: 1168510.6 | C27: 3 | E27: 0.1012 | F27: =(F26+1)*(E27+1)-1 -> 0.31017618 | I27: 0.10515393 | J27: =(J26+1)*(I27+1)-1 -> 0.36265693 | M27: 0.1258 | N27: =(N26+1)*(M27+1)-1 -> 0.41679381
A28: 41090 | B28: 1130118.4 | C28: 3 | E28: -0.0343 | F28: =(F27+1)*(E28+1)-1 -> 0.26523714 | I28: -0.03117511 | J28: =(J27+1)*(I28+1)-1 -> 0.32017595 | M28: -0.0275 | N28: =(N27+1)*(M28+1)-1 -> 0.37783198
A29: 41182 | B29: 1189048.6 | C29: 3 | E29: 0.0521 | F29: =(F28+1)*(E29+1)-1 -> 0.33115599 | I29: 0.05586506 | J29: =(J28+1)*(I29+1)-1 -> 0.39392765 | M29: 0.0635 | N29: =(N28+1)*(M29+1)-1 -> 0.46532432
A30: 41274 | B30: 1172480 | C30: 3 | E30: -0.0139 | F30: =(F29+1)*(E30+1)-1 -> 0.31265292 | I30: -0.01216298 | J30: =(J29+1)*(I30+1)-1 -> 0.37697334 | M30: -0.0038 | N30: =(N29+1)*(M30+1)-1 -> 0.45975608
A31: 41364 | B31: 1246310 | C31: 3 | E31: 0.0638 | F31: =(F30+1)*(E31+1)-1 -> 0.39640018 | I31: 0.06568468 | J31: =(J30+1)*(I31+1)-1 -> 0.46741939 | M31: 0.1061 | N31: =(N30+1)*(M31+1)-1 -> 0.6146362
A32: 41455 | B32: 1224175.1 | C32: 3 | E32: -0.0012 | F32: =(F31+1)*(E32+1)-1 -> 0.3947245 | I32: 0.00126069 | J32: =(J31+1)*(I32+1)-1 -> 0.46926935 | M32: 0.0291 | N32: =(N31+1)*(M32+1)-1 -> 0.66162212
A33: 41547 | B33: 1266447.1 | C33: 3 | E33: 0.0251 | F33: =(F32+1)*(E33+1)-1 -> 0.42973209 | I33: 0.02829394 | J33: =(J32+1)*(I33+1)-1 -> 0.51084077 | M33: 0.0524 | N33: =(N32+1)*(M33+1)-1 -> 0.74869112
A34: 41639 | B34: 1308660.8 | C34: 3 | E34: 0.0382 | F34: =(F33+1)*(E34+1)-1 -> 0.48434785 | I34: 0.0405503 | J34: =(J33+1)*(I34+1)-1 -> 0.57210582 | M34: 0.1051 | N34: =(N33+1)*(M34+1)-1 -> 0.93247855
... A52: 42369 | B52: 308645.25 | C52: 2 | E52: -0.0187 | F52: =(F51+1)*(E52+1)-1 -> 0.5002655 | I52: -0.0174 | J52: =(J51+1)*(I52+1)-1 -> 0.6613753 | M52: -0.0158 | N52: =(N51+1)*(M52+1)-1 -> 1.2277254
