Workbook
Name ChampsData: WatchList!$A$6:$B$20
Name ChampsData: #REF!
Name ContendersData: #REF!
Name CzallengersData: #REF!
Name DataAll: Challengers!#REF!
Name DataAll: Champions!$A$7:$BC$152
Name DataAll: Contenders!$A$7:$BC$221
Name DataAll: Historical!$A$7:$BG$411
Name DataAll: 'All CCC'!$A$7:$BC$367
Name Deletions: Changes!$A$162:$I$1098
Name FrozenAngels: Notes!$A$181:$J$197
Name NearChallengers: Notes!#REF!
Name WatchList: WatchList!$A$6:$B$20

Sheet Title
M6: The Dividend Champions List
M8: A Resource For Dividend Growth Investors
M18: A monthly publication tracking companies with a history of consistently increasing their dividends
M20: To be included on the list, a company must be consistently increasing its calendar year dividend payout for at least the past 5 years
M34: Created by David Fish
M36: Updated by Justin Law
M38: ©2026 All Rights Reserved. This listing is intended for personal, non-commercial use only.

Sheet Champions
A1: U.S. Dividend Champions | C1: Sign up for free updates at: | J1: Dividend Information | Z1: Fundamental Data | AC1: Numbers in Blue directly from Finviz | AO1: Special | AR1: Dividend Growth Model | AY1: Technical Data | BD1: Other
A2: (and American Depository Receipts) | C2: https://www.ireitinvestor.com/dividend-champions/ | J2: DEG=Dividend to Earnings Growth; A/D=Acceleration/Deceleration; DGR=Dividend Growth Rate | Z2: EPS=Earnings Per Share; P/E=Price/Earnings Per Share; TTM=Trailing Twelve Months; FYE=Fiscal Year End; MRQ=Most Recent Quarter; ROE = Return on Equity | AO2: (see Notes tab) | AR2: (based on Earnings Estimates, if available) | AY2: MMA=Moving Market Average
A3: 46142 | J3: Dates in Red (right-aligned) indicate last increase more than a year ago (Ex-Div Date) | Q3: Dates in Green (centered) indicate increase (by Ex-Div. Date) expected in next 2 months | AR3: Past Performance is No Guarantee of Future Results
J4: Numbers in Gray last updated 12/31/2025 | Z4: Disclaimer: Although all figures are thought to be correct, no guarantee is expressed or implied. | AR4: Last updated 12/31/2025 | AW4: 5-year Total | AZ4: Current Price as % from:
A5: Company | B5: Ticker | E5: No. | F5: CCC | G5: DRIP Fees | I5: 46142 | J5: Div. | K5: Current | L5: Payouts/ | N5: Qtly | O5: Previous | P5: Last Increased on: | R5: MR% | S5: DGR | T5: DGR | U5: DGR | V5: DGR | W5: 5/10 | X5: Past 5yr | Y5: &=MultiIncThisYr | Z5: EPS% | AA5: TTM | AB5: FYE | AC5: TTM | AE5: TTM | AF5: MRQ | AG5: TTM | AH5: TTM | AI5: NY | AJ5: Past 5yr | AK5: Est-5yr | AL5: MktCap | AM5: Inside | AN5: Debt/ | AO5: Tweed | AP5: Chowder | AQ5: +/-% vs. | AR5: Estimated Dividends to be Paid in Year: | AW5: Est. Payback | AY5: 5-yr | AZ5: 52-wk | BA5: 52-wk | BB5: 50-day | BC5: 200-day | BE5: Streak | BF5: Recessions | BG5: TTM | BH5: Dividend
A6: Name | B6: Symbol | C6: Sector | D6: Industry | E6: Yrs | F6: Seq | G6: DR | H6: SP | I6: Price | J6: Yield | K6: Dividend | L6: Year | M6: Annualized | N6: Sch | O6: Payout | P6: Ex-Div | Q6: Pay | R6: Inc. | S6: 1-yr | T6: 3-yr | U6: 5-yr | V6: 10-yr | W6: A/D* | X6: DEG | Y6: Notes | Z6: Payout | AA6: P/E | AB6: Month | AC6: EPS | AD6: PEG | AE6: P/Sales | AF6: P/Book | AG6: ROE | AH6: Growth | AI6: Growth | AJ6: Growth | AK6: Growth | AL6: ($Mil) | AM6: Own. | AN6: Equity | AO6: Factor | AP6: Rule | AQ6: Graham | AR6: 2024 | AS6: 2025 | AT6: 2026 | AU6: 2027 | AV6: 2028 | AW6: $ | AX6: % | AY6: Beta | AZ6: Low | BA6: High | BB6: MMA | BC6: MMA | BD6: OTC | BE6: Began | BF6: Survived | BG6: ROA | BH6: Currency | BI6: Tax
A7: ABM Industries Incorporated | B7: ABM | C7: Industrials | D7: Commercial Services & Supplies | E7: 59 | F7: 18 | G7: Y | H7: N | I7: 40.8 | J7: =(M7/I7)*100 -> 2.8431373 | K7: 0.29 | L7: 4 | M7: =K7*L7 -> 1.16 | N7: B05 | O7: 0.265 | P7: 46038 | Q7: 46055 | R7: =(K7-O7)/O7*100 -> 9.4339623 | S7: =IF(INDEX(Historical!$D$7:$D1047,MATCH(B7,Historical!$B$7:$B$1044,0))=0,"n/a",(INDEX(Historical!$C$7:$C$1044,MATCH(B7,Historical!$B$7:$B$1044,0))/INDEX(Historical!$D$7:$D$1044,MATCH(B7,Historical!$B$7:$B$1044,0))-1)*100) -> 17.777778 | T7: =IF(INDEX(Historical!$F$7:$F$1044,MATCH(B7,Historical!$B$7:$B$1044,0))=0,"n/a",((INDEX(Historical!$C$7:$C$1044,MATCH(B7,Historical!$B$7:$B$1044,0))/INDEX(Historical!$F$7:$F$1044,MATCH(B7,Historical!$B$7:$B$1044,0)))^(1/3)-1)*100) -> 10.765307 | U7: =IF(INDEX(Historical!$H$7:$H$1044,MATCH(B7,Historical!$B$7:$B$1044,0))=0,"n/a",((INDEX(Historical!$C$7:$C$1044,MATCH(B7,Historical!$B$7:$B$1044,0))/INDEX(Historical!$H$7:$H$1044,MATCH(B7,Historical!$B$7:$B$1044,0)))^(1/5)-1)*100) -> 7.4520806 | V7: =IF(INDEX(Historical!$M$7:$M$1044,MATCH(B7,Historical!$B$7:$B$1044,0))=0,"n/a",((INDEX(Historical!$C$7:$C$1044,MATCH(B7,Historical!$B$7:$B$1044,0))/INDEX(Historical!$M$7:$M$1044,MATCH(B7,Historical!$B$7:$B$1044,0)))^(1/10)-1)*100) -> 5.1750166 | W7: =IF(OR(U7<=0,U7="n/a",V7<=0,V7="n/a"),"n/a",U7/V7) -> 1.440011 | X7: =IF(OR(AJ7<=0,AJ7="n/a",U7<=0,U7="n/a"),"n/a",U7/AJ7) -> 0.029056344 | Z7: =IF(OR(AC7<0.01,AC7="n/a"),"n/a",M7/AC7*100) -> 45.669291 | AA7: =IF(OR(AC7<0.01,AC7="n/a"),"n/a",I7/AC7) -> 16.062992 | AB7: 10 | AC7: 2.54 | AD7: 0.92 | AE7: 0.27 | AF7: 1.39 | AG7: 9 | AH7: 15.09 | AI7: 9.5 | AJ7: 256.47 | AK7: 10.25 | AL7: 2390 | AM7: 1.68 | AN7: 1.01 | AO7: =IF(U7="n/a","n/a",IF(AA7<0,"n/a",IF(AA7="n/a","n/a",J7+U7-AA7))) -> -5.7677743 | AP7: =IF(U7="n/a","n/a",J7+U7) -> 10.295218 | AQ7: =IF(OR(AC7<0.01,AC7="n/a",AF7="n/a"),"n/a",(I7/SQRT(22.5*AC7*(I7/AF7))-1)*100) -> -0.38393915 | AR7: =INDEX(Historical!$C$7:$C$1045,MATCH(B7,Historical!$B$7:$B$1045,0))*IF(AH7="n/a",1.03,IF(AH7<0,1.01,IF(AH7>10,1.1,(1+AH7/100)))) -> 1.166 | AS7: =IF($AI7="n/a",1.03*AR7,IF($AI7<0,1.01*AR7,IF($AI7>10,1.1*AR7,(1+$AI7/100)*AR7))) -> 1.27677 | AT7: =IF($AK7="n/a",1.03*AS7,IF($AK7<0,1.01*AS7,IF($AK7>10,1.1*AS7,(1+$AK7/100)*AS7))) -> 1.404447 | AU7: =IF($AK7="n/a",1.03*AT7,IF($AK7<0,1.01*AT7,IF($AK7>10,1.1*AT7,(1+$AK7/100)*AT7))) -> 1.5448917 | AV7: =IF($AK7="n/a",1.03*AU7,IF($AK7<0,1.01*AU7,IF($AK7>10,1.1*AU7,(1+$AK7/100)*AU7))) -> 1.6993809 | AW7: =SUM(AR7:AV7) -> 7.0914896 | AX7: =AW7/I7*100 -> 17.381102 | AY7: 0.72 | AZ7: 10.38 | BA7: -22.93 | BB7: 0.72 | BC7: -7.65 | BE7: 1968 | BF7: =IF(BE7>2020,0,IF(BE7>2008,1,IF(BE7>2001,2,IF(BE7>1990,3,IF(BE7>1980,4,IF(BE7>1973,5,IF(BE7>1970,6,IF(BE7>1960,7,IF(BE7>1958,8,IF(BE7>1953,9,10)))))))))) -> 7 | BG7: 3 | BH7: USD | BI7: Corp
A8: Archer-Daniels-Midland Company | B8: ADM | C8: Consumer Staples | D8: Food Products | E8: 51 | F8: 47 | G8: N | H8: Y | I8: 74.54 | J8: =(M8/I8)*100 -> 2.7904481 | K8: 0.52 | L8: 4 | M8: =K8*L8 -> 2.08 | N8: C13 | O8: 0.51 | P8: 46070 | Q8: 46091 | R8: =(K8-O8)/O8*100 -> 1.9607843 | S8: =IF(INDEX(Historical!$D$7:$D1054,MATCH(B8,Historical!$B$7:$B$1044,0))=0,"n/a",(INDEX(Historical!$C$7:$C$1044,MATCH(B8,Historical!$B$7:$B$1044,0))/INDEX(Historical!$D$7:$D$1044,MATCH(B8,Historical!$B$7:$B$1044,0))-1)*100) -> 2 | T8: =IF(INDEX(Historical!$F$7:$F$1044,MATCH(B8,Historical!$B$7:$B$1044,0))=0,"n/a",((INDEX(Historical!$C$7:$C$1044,MATCH(B8,Historical!$B$7:$B$1044,0))/INDEX(Historical!$F$7:$F$1044,MATCH(B8,Historical!$B$7:$B$1044,0)))^(1/3)-1)*100) -> 8.4351443 | U8: =IF(INDEX(Historical!$H$7:$H$1044,MATCH(B8,Historical!$B$7:$B$1044,0))=0,"n/a",((INDEX(Historical!$C$7:$C$1044,MATCH(B8,Historical!$B$7:$B$1044,0))/INDEX(Historical!$H$7:$H$1044,MATCH(B8,Historical!$B$7:$B$1044,0)))^(1/5)-1)*100) -> 7.2145026 | V8: =IF(INDEX(Historical!$M$7:$M$1044,MATCH(B8,Historical!$B$7:$B$1044,0))=0,"n/a",((INDEX(Historical!$C$7:$C$1044,MATCH(B8,Historical!$B$7:$B$1044,0))/INDEX(Historical!$M$7:$M$1044,MATCH(B8,Historical!$B$7:$B$1044,0)))^(1/10)-1)*100) -> 6.1796317 | W8: =IF(OR(U8<=0,U8="n/a",V8<=0,V8="n/a"),"n/a",U8/V8) -> 1.1674648 | X8: =IF(OR(AJ8<=0,AJ8="n/a",U8<=0,U8="n/a"),"n/a",U8/AJ8) -> n/a | Z8: =IF(OR(AC8<0.01,AC8="n/a"),"n/a",M8/AC8*100) -> 93.273543 | AA8: =IF(OR(AC8<0.01,AC8="n/a"),"n/a",I8/AC8) -> 33.426009 | AB8: 6 | AC8: 2.23 | AD8: 0.99 | AE8: 0.45 | AF8: 1.57 | AG8: 4.8 | AH8: 21.35 | AI8: 16.27 | AJ8: -6.68 | AK8: 15.62 | AL8: 35920 | AM8: 0.68 | AN8: 0.43 | AO8: =IF(U8="n/a","n/a",IF(AA8<0,"n/a",IF(AA8="n/a","n/a",J8+U8-AA8))) -> -23.421058 | AP8: =IF(U8="n/a","n/a",J8+U8) -> 10.004951 | AQ8: =IF(OR(AC8<0.01,AC8="n/a",AF8="n/a"),"n/a",(I8/SQRT(22.5*AC8*(I8/AF8))-1)*100) -> 52.721728 | AR8: =INDEX(Historical!$C$7:$C$1045,MATCH(B8,Historical!$B$7:$B$1045,0))*IF(AH8="n/a",1.03,IF(AH8<0,1.01,IF(AH8>10,1.1,(1+AH8/100)))) -> 2.244 | AS8: =IF($AI8="n/a",1.03*AR8,IF($AI8<0,1.01*AR8,IF($AI8>10,1.1*AR8,(1+$AI8/100)*AR8))) -> 2.4684 | AT8: =IF($AK8="n/a",1.03*AS8,IF($AK8<0,1.01*AS8,IF($AK8>10,1.1*AS8,(1+$AK8/100)*AS8))) -> 2.71524 | AU8: =IF($AK8="n/a",1.03*AT8,IF($AK8<0,1.01*AT8,IF($AK8>10,1.1*AT8,(1+$AK8/100)*AT8))) -> 2.986764 | AV8: =IF($AK8="n/a",1.03*AU8,IF($AK8<0,1.01*AU8,IF($AK8>10,1.1*AU8,(1+$AK8/100)*AU8))) -> 3.2854404 | AW8: =SUM(AR8:AV8) -> 13.699844 | AX8: =AW8/I8*100 -> 18.379185 | AY8: 0.58 | AZ8: 59.24 | BA8: -0.47 | BB8: 6.48 | BC8: 18.08 | BE8: 1976 | BF8: =IF(BE8>2020,0,IF(BE8>2008,1,IF(BE8>2001,2,IF(BE8>1990,3,IF(BE8>1980,4,IF(BE8>1973,5,IF(BE8>1970,6,IF(BE8>1960,7,IF(BE8>1958,8,IF(BE8>1953,9,10)))))))))) -> 5 | BG8: 2.04 | BH8: USD | BI8: Corp
A9: Automatic Data Processing, Inc. | B9: ADP | C9: Industrials | D9: Professional Services | E9: 50 | F9: 51 | G9: N | H9: Y | I9: 211.91 | J9: =(M9/I9)*100 -> 3.2089094 | K9: 1.7 | L9: 4 | M9: =K9*L9 -> 6.8 | N9: A01 | O9: 1.54 | P9: 46003 | Q9: 46023 | R9: =(K9-O9)/O9*100 -> 10.38961 | S9: =IF(INDEX(Historical!$D$7:$D1055,MATCH(B9,Historical!$B$7:$B$1044,0))=0,"n/a",(INDEX(Historical!$C$7:$C$1044,MATCH(B9,Historical!$B$7:$B$1044,0))/INDEX(Historical!$D$7:$D$1044,MATCH(B9,Historical!$B$7:$B$1044,0))-1)*100) -> 10 | T9: =IF(INDEX(Historical!$F$7:$F$1044,MATCH(B9,Historical!$B$7:$B$1044,0))=0,"n/a",((INDEX(Historical!$C$7:$C$1044,MATCH(B9,Historical!$B$7:$B$1044,0))/INDEX(Historical!$F$7:$F$1044,MATCH(B9,Historical!$B$7:$B$1044,0)))^(1/3)-1)*100) -> 13.980125 | U9: =IF(INDEX(Historical!$H$7:$H$1044,MATCH(B9,Historical!$B$7:$B$1044,0))=0,"n/a",((INDEX(Historical!$C$7:$C$1044,MATCH(B9,Historical!$B$7:$B$1044,0))/INDEX(Historical!$H$7:$H$1044,MATCH(B9,Historical!$B$7:$B$1044,0)))^(1/5)-1)*100) -> 11.095346 | V9: =IF(INDEX(Historical!$M$7:$M$1044,MATCH(B9,Historical!$B$7:$B$1044,0))=0,"n/a",((INDEX(Historical!$C$7:$C$1044,MATCH(B9,Historical!$B$7:$B$1044,0))/INDEX(Historical!$M$7:$M$1044,MATCH(B9,Historical!$B$7:$B$1044,0)))^(1/10)-1)*100) -> 12.132748 | W9: =IF(OR(U9<=0,U9="n/a",V9<=0,V9="n/a"),"n/a",U9/V9) -> 0.91449573 | X9: =IF(OR(AJ9<=0,AJ9="n/a",U9<=0,U9="n/a"),"n/a",U9/AJ9) -> 0.93552664 | Z9: =IF(OR(AC9<0.01,AC9="n/a"),"n/a",M9/AC9*100) -> 63.373719 | AA9: =IF(OR(AC9<0.01,AC9="n/a"),"n/a",I9/AC9) -> 19.749301 | AB9: 6 | AC9: 10.73 | AD9: 1.78 | AE9: 3.95 | AF9: 13.37 | AG9: 71.2 | AH9: 10.32 | AI9: 9.91 | AJ9: 11.86 | AK9: 9.79 | AL9: 85320 | AM9: 0.15 | AN9: 0.68 | AO9: =IF(U9="n/a","n/a",IF(AA9<0,"n/a",IF(AA9="n/a","n/a",J9+U9-AA9))) -> -5.4450456 | AP9: =IF(U9="n/a","n/a",J9+U9) -> 14.304255 | AQ9: =IF(OR(AC9<0.01,AC9="n/a",AF9="n/a"),"n/a",(I9/SQRT(22.5*AC9*(I9/AF9))-1)*100) -> 242.57077 | AR9: =INDEX(Historical!$C$7:$C$1045,MATCH(B9,Historical!$B$7:$B$1045,0))*IF(AH9="n/a",1.03,IF(AH9<0,1.01,IF(AH9>10,1.1,(1+AH9/100)))) -> 6.776 | AS9: =IF($AI9="n/a",1.03*AR9,IF($AI9<0,1.01*AR9,IF($AI9>10,1.1*AR9,(1+$AI9/100)*AR9))) -> 7.4475016 | AT9: =IF($AK9="n/a",1.03*AS9,IF($AK9<0,1.01*AS9,IF($AK9>10,1.1*AS9,(1+$AK9/100)*AS9))) -> 8.176612 | AU9: =IF($AK9="n/a",1.03*AT9,IF($AK9<0,1.01*AT9,IF($AK9>10,1.1*AT9,(1+$AK9/100)*AT9))) -> 8.9771023 | AV9: =IF($AK9="n/a",1.03*AU9,IF($AK9<0,1.01*AU9,IF($AK9>10,1.1*AU9,(1+$AK9/100)*AU9))) -> 9.8559606 | AW9: =SUM(AR9:AV9) -> 41.233177 | AX9: =AW9/I9*100 -> 19.457872 | AY9: 0.86 | AZ9: 12.62 | BA9: -35.77 | BB9: 2.42 | BC9: -17.61 | BE9: 1976 | BF9: =IF(BE9>2020,0,IF(BE9>2008,1,IF(BE9>2001,2,IF(BE9>1990,3,IF(BE9>1980,4,IF(BE9>1973,5,IF(BE9>1970,6,IF(BE9>1960,7,IF(BE9>1958,8,IF(BE9>1953,9,10)))))))))) -> 5 | BG9: 7.19 | BH9: USD | BI9: Corp
A10: Aflac Incorporated | B10: AFL | C10: Financials | D10: Insurance | E10: 44 | F10: 61 | G10: N | H10: N | I10: 113.67 | J10: =(M10/I10)*100 -> 2.1465646 | K10: 0.61 | L10: 4 | M10: =K10*L10 -> 2.44 | N10: C01 | O10: 0.58 | P10: 46071 | Q10: 46083 | R10: =(K10-O10)/O10*100 -> 5.1724138 | S10: =IF(INDEX(Historical!$D$7:$D1060,MATCH(B10,Historical!$B$7:$B$1044,0))=0,"n/a",(INDEX(Historical!$C$7:$C$1044,MATCH(B10,Historical!$B$7:$B$1044,0))/INDEX(Historical!$D$7:$D$1044,MATCH(B10,Historical!$B$7:$B$1044,0))-1)*100) -> 16 | T10: =IF(INDEX(Historical!$F$7:$F$1044,MATCH(B10,Historical!$B$7:$B$1044,0))=0,"n/a",((INDEX(Historical!$C$7:$C$1044,MATCH(B10,Historical!$B$7:$B$1044,0))/INDEX(Historical!$F$7:$F$1044,MATCH(B10,Historical!$B$7:$B$1044,0)))^(1/3)-1)*100) -> 13.18512 | U10: =IF(INDEX(Historical!$H$7:$H$1044,MATCH(B10,Historical!$B$7:$B$1044,0))=0,"n/a",((INDEX(Historical!$C$7:$C$1044,MATCH(B10,Historical!$B$7:$B$1044,0))/INDEX(Historical!$H$7:$H$1044,MATCH(B10,Historical!$B$7:$B$1044,0)))^(1/5)-1)*100) -> 15.678858 | V10: =IF(INDEX(Historical!$M$7:$M$1044,MATCH(B10,Historical!$B$7:$B$1044,0))=0,"n/a",((INDEX(Historical!$C$7:$C$1044,MATCH(B10,Historical!$B$7:$B$1044,0))/INDEX(Historical!$M$7:$M$1044,MATCH(B10,Historical!$B$7:$B$1044,0)))^(1/10)-1)*100) -> 11.374583 | W10: =IF(OR(U10<=0,U10="n/a",V10<=0,V10="n/a"),"n/a",U10/V10) -> 1.3784117 | X10: =IF(OR(AJ10<=0,AJ10="n/a",U10<=0,U10="n/a"),"n/a",U10/AJ10) -> 36.46246 | Z10: =IF(OR(AC10<0.01,AC10="n/a"),"n/a",M10/AC10*100) -> 27.6958 | AA10: =IF(OR(AC10<0.01,AC10="n/a"),"n/a",I10/AC10) -> 12.902384 | AB10: 12 | AC10: 8.81 | AD10: 5.53 | AE10: 3.24 | AF10: 2.59 | AG10: 19.01 | AH10: -3.78 | AI10: 7.22 | AJ10: 0.43 | AK10: 2.66 | AL10: 58560 | AM10: 10.82 | AN10: 0.35 | AO10: =IF(U10="n/a","n/a",IF(AA10<0,"n/a",IF(AA10="n/a","n/a",J10+U10-AA10))) -> 4.9230389 | AP10: =IF(U10="n/a","n/a",J10+U10) -> 17.825423 | AQ10: =IF(OR(AC10<0.01,AC10="n/a",AF10="n/a"),"n/a",(I10/SQRT(22.5*AC10*(I10/AF10))-1)*100) -> 21.869099 | AR10: =INDEX(Historical!$C$7:$C$1045,MATCH(B10,Historical!$B$7:$B$1045,0))*IF(AH10="n/a",1.03,IF(AH10<0,1.01,IF(AH10>10,1.1,(1+AH10/100)))) -> 2.3432 | AS10: =IF($AI10="n/a",1.03*AR10,IF($AI10<0,1.01*AR10,IF($AI10>10,1.1*AR10,(1+$AI10/100)*AR10))) -> 2.512379 | AT10: =IF($AK10="n/a",1.03*AS10,IF($AK10<0,1.01*AS10,IF($AK10>10,1.1*AS10,(1+$AK10/100)*AS10))) -> 2.5792083 | AU10: =IF($AK10="n/a",1.03*AT10,IF($AK10<0,1.01*AT10,IF($AK10>10,1.1*AT10,(1+$AK10/100)*AT10))) -> 2.6478153 | AV10: =IF($AK10="n/a",1.03*AU10,IF($AK10<0,1.01*AU10,IF($AK10>10,1.1*AU10,(1+$AK10/100)*AU10))) -> 2.7182471 | AW10: =SUM(AR10:AV10) -> 12.80085 | AX10: =AW10/I10*100 -> 11.261414 | AY10: 0.64 | AZ10: 17.25 | BA10: -4.74 | BB10: 2.02 | BC10: 3.89 | BE10: 1983 | BF10: =IF(BE10>2020,0,IF(BE10>2008,1,IF(BE10>2001,2,IF(BE10>1990,3,IF(BE10>1980,4,IF(BE10>1973,5,IF(BE10>1970,6,IF(BE10>1960,7,IF(BE10>1958,8,IF(BE10>1953,9,10)))))))))) -> 4 | BG10: 3.86 | BH10: USD | BI10: Corp
A11: Albemarle Corporation | B11: ALB | C11: Materials | D11: Chemicals | E11: 31 | F11: 114 | G11: N | H11: N | I11: 196.7 | J11: =(M11/I11)*100 -> 0.82358922 | K11: 0.405 | L11: 4 | M11: =K11*L11 -> 1.62 | N11: A02 | O11: 0.4 | P11: 45548 | Q11: 45566 | R11: =(K11-O11)/O11*100 -> 1.25 | S11: =IF(INDEX(Historical!$D$7:$D1068,MATCH(B11,Historical!$B$7:$B$1044,0))=0,"n/a",(INDEX(Historical!$C$7:$C$1044,MATCH(B11,Historical!$B$7:$B$1044,0))/INDEX(Historical!$D$7:$D$1044,MATCH(B11,Historical!$B$7:$B$1044,0))-1)*100) -> 0.93457944 | T11: =IF(INDEX(Historical!$F$7:$F$1044,MATCH(B11,Historical!$B$7:$B$1044,0))=0,"n/a",((INDEX(Historical!$C$7:$C$1044,MATCH(B11,Historical!$B$7:$B$1044,0))/INDEX(Historical!$F$7:$F$1044,MATCH(B11,Historical!$B$7:$B$1044,0)))^(1/3)-1)*100) -> 0.94345194 | U11: =IF(INDEX(Historical!$H$7:$H$1044,MATCH(B11,Historical!$B$7:$B$1044,0))=0,"n/a",((INDEX(Historical!$C$7:$C$1044,MATCH(B11,Historical!$B$7:$B$1044,0))/INDEX(Historical!$H$7:$H$1044,MATCH(B11,Historical!$B$7:$B$1044,0)))^(1/5)-1)*100) -> 1.2491865 | V11: =IF(INDEX(Historical!$M$7:$M$1044,MATCH(B11,Historical!$B$7:$B$1044,0))=0,"n/a",((INDEX(Historical!$C$7:$C$1044,MATCH(B11,Historical!$B$7:$B$1044,0))/INDEX(Historical!$M$7:$M$1044,MATCH(B11,Historical!$B$7:$B$1044,0)))^(1/10)-1)*100) -> 3.5311297 | W11: =IF(OR(U11<=0,U11="n/a",V11<=0,V11="n/a"),"n/a",U11/V11) -> 0.35376399 | X11: =IF(OR(AJ11<=0,AJ11="n/a",U11<=0,U11="n/a"),"n/a",U11/AJ11) -> n/a | Y11: 2025 = Year 31 | Z11: =IF(OR(AC11<0.01,AC11="n/a"),"n/a",M11/AC11*100) -> n/a | AA11: =IF(OR(AC11<0.01,AC11="n/a"),"n/a",I11/AC11) -> n/a | AB11: 12 | AC11: -5.76 | AD11: n/a | AE11: 4.51 | AF11: 3.17 | AG11: -5.24 | AH11: 1222.73 | AI11: 6.72 | AJ11: n/a | AK11: n/a | AL11: 23180 | AM11: 0.29 | AN11: 0.35 | AO11: =IF(U11="n/a","n/a",IF(AA11<0,"n/a",IF(AA11="n/a","n/a",J11+U11-AA11))) -> n/a | AP11: =IF(U11="n/a","n/a",J11+U11) -> 2.0727758 | AQ11: =IF(OR(AC11<0.01,AC11="n/a",AF11="n/a"),"n/a",(I11/SQRT(22.5*AC11*(I11/AF11))-1)*100) -> n/a | AR11: =INDEX(Historical!$C$7:$C$1045,MATCH(B11,Historical!$B$7:$B$1045,0))*IF(AH11="n/a",1.03,IF(AH11<0,1.01,IF(AH11>10,1.1,(1+AH11/100)))) -> 1.782 | AS11: =IF($AI11="n/a",1.03*AR11,IF($AI11<0,1.01*AR11,IF($AI11>10,1.1*AR11,(1+$AI11/100)*AR11))) -> 1.9017504 | AT11: =IF($AK11="n/a",1.03*AS11,IF($AK11<0,1.01*AS11,IF($AK11>10,1.1*AS11,(1+$AK11/100)*AS11))) -> 1.9588029 | AU11: =IF($AK11="n/a",1.03*AT11,IF($AK11<0,1.01*AT11,IF($AK11>10,1.1*AT11,(1+$AK11/100)*AT11))) -> 2.017567 | AV11: =IF($AK11="n/a",1.03*AU11,IF($AK11<0,1.01*AU11,IF($AK11>10,1.1*AU11,(1+$AK11/100)*AU11))) -> 2.078094 | AW11: =SUM(AR11:AV11) -> 9.7382143 | AX11: =AW11/I11*100 -> 4.9507953 | AY11: 1.36 | AZ11: 266.29 | BA11: -8.81 | BB11: 10.27 | BC11: 52.08 | BE11: 1995 | BF11: =IF(BE11>2020,0,IF(BE11>2008,1,IF(BE11>2001,2,IF(BE11>1990,3,IF(BE11>1980,4,IF(BE11>1973,5,IF(BE11>1970,6,IF(BE11>1960,7,IF(BE11>1958,8,IF(BE11>1953,9,10)))))))))) -> 3 | BG11: -3.1 | BH11: USD | BI11: Corp
A12: Alerus Financial Corporation | B12: ALRS | C12: Financials | D12: Diversified Financial Services | E12: 27 | F12: 137 | G12: - | H12: - | I12: 26.94 | J12: =(M12/I12)*100 -> 3.1180401 | K12: 0.21 | L12: 4 | M12: =K12*L12 -> 0.84 | N12: A10 | O12: 0.2 | P12: 45835 | Q12: 45849 | R12: =(K12-O12)/O12*100 -> 5 | S12: =IF(INDEX(Historical!$D$7:$D1072,MATCH(B12,Historical!$B$7:$B$1044,0))=0,"n/a",(INDEX(Historical!$C$7:$C$1044,MATCH(B12,Historical!$B$7:$B$1044,0))/INDEX(Historical!$D$7:$D$1044,MATCH(B12,Historical!$B$7:$B$1044,0))-1)*100) -> 5.1282051 | T12: =IF(INDEX(Historical!$F$7:$F$1044,MATCH(B12,Historical!$B$7:$B$1044,0))=0,"n/a",((INDEX(Historical!$C$7:$C$1044,MATCH(B12,Historical!$B$7:$B$1044,0))/INDEX(Historical!$F$7:$F$1044,MATCH(B12,Historical!$B$7:$B$1044,0)))^(1/3)-1)*100) -> 6.439211 | U12: =IF(INDEX(Historical!$H$7:$H$1044,MATCH(B12,Historical!$B$7:$B$1044,0))=0,"n/a",((INDEX(Historical!$C$7:$C$1044,MATCH(B12,Historical!$B$7:$B$1044,0))/INDEX(Historical!$H$7:$H$1044,MATCH(B12,Historical!$B$7:$B$1044,0)))^(1/5)-1)*100) -> 6.446778 | V12: =IF(INDEX(Historical!$M$7:$M$1044,MATCH(B12,Historical!$B$7:$B$1044,0))=0,"n/a",((INDEX(Historical!$C$7:$C$1044,MATCH(B12,Historical!$B$7:$B$1044,0))/INDEX(Historical!$M$7:$M$1044,MATCH(B12,Historical!$B$7:$B$1044,0)))^(1/10)-1)*100) -> 7.1773463 | W12: =IF(OR(U12<=0,U12="n/a",V12<=0,V12="n/a"),"n/a",U12/V12) -> 0.89821192 | X12: =IF(OR(AJ12<=0,AJ12="n/a",U12<=0,U12="n/a"),"n/a",U12/AJ12) -> n/a | Z12: =IF(OR(AC12<0.01,AC12="n/a"),"n/a",M12/AC12*100) -> 80.769231 | AA12: =IF(OR(AC12<0.01,AC12="n/a"),"n/a",I12/AC12) -> 25.903846 | AB12: 12 | AC12: 1.04 | AD12: n/a | AE12: 2.06 | AF12: 1.18 | AG12: 5 | AH12: -7.37 | AI12: 6.12 | AJ12: -23.04 | AK12: n/a | AL12: 688.6 | AM12: 9.39 | AN12: 0.53 | AO12: =IF(U12="n/a","n/a",IF(AA12<0,"n/a",IF(AA12="n/a","n/a",J12+U12-AA12))) -> -16.339028 | AP12: =IF(U12="n/a","n/a",J12+U12) -> 9.5648181 | AQ12: =IF(OR(AC12<0.01,AC12="n/a",AF12="n/a"),"n/a",(I12/SQRT(22.5*AC12*(I12/AF12))-1)*100) -> 16.555258 | AR12: =INDEX(Historical!$C$7:$C$1045,MATCH(B12,Historical!$B$7:$B$1045,0))*IF(AH12="n/a",1.03,IF(AH12<0,1.01,IF(AH12>10,1.1,(1+AH12/100)))) -> 0.8282 | AS12: =IF($AI12="n/a",1.03*AR12,IF($AI12<0,1.01*AR12,IF($AI12>10,1.1*AR12,(1+$AI12/100)*AR12))) -> 0.87888584 | AT12: =IF($AK12="n/a",1.03*AS12,IF($AK12<0,1.01*AS12,IF($AK12>10,1.1*AS12,(1+$AK12/100)*AS12))) -> 0.90525242 | AU12: =IF($AK12="n/a",1.03*AT12,IF($AK12<0,1.01*AT12,IF($AK12>10,1.1*AT12,(1+$AK12/100)*AT12))) -> 0.93240999 | AV12: =IF($AK12="n/a",1.03*AU12,IF($AK12<0,1.01*AU12,IF($AK12>10,1.1*AU12,(1+$AK12/100)*AU12))) -> 0.96038229 | AW12: =SUM(AR12:AV12) -> 4.5051305 | AX12: =AW12/I12*100 -> 16.72283 | AY12: 0.65 | AZ12: 38.48 | BA12: 2.36 | BB12: 9.76 | BC12: 17.18 | BE12: 1999 | BF12: =IF(BE12>2020,0,IF(BE12>2008,1,IF(BE12>2001,2,IF(BE12>1990,3,IF(BE12>1980,4,IF(BE12>1973,5,IF(BE12>1970,6,IF(BE12>1960,7,IF(BE12>1958,8,IF(BE12>1953,9,10)))))))))) -> 3 | BG12: 0.51 | BH12: USD | BI12: Corp
A13: A. O. Smith Corporation | B13: AOS | C13: Industrials | D13: Building Products | E13: 32 | F13: 110 | G13: N | H13: N | I13: 61.84 | J13: =(M13/I13)*100 -> 2.3285899 | K13: 0.36 | L13: 4 | M13: =K13*L13 -> 1.44 | N13: B15 | O13: 0.34 | P13: 45961 | Q13: 45978 | R13: =(K13-O13)/O13*100 -> 5.8823529 | S13: =IF(INDEX(Historical!$D$7:$D1082,MATCH(B13,Historical!$B$7:$B$1044,0))=0,"n/a",(INDEX(Historical!$C$7:$C$1044,MATCH(B13,Historical!$B$7:$B$1044,0))/INDEX(Historical!$D$7:$D$1044,MATCH(B13,Historical!$B$7:$B$1044,0))-1)*100) -> 6.1538462 | T13: =IF(INDEX(Historical!$F$7:$F$1044,MATCH(B13,Historical!$B$7:$B$1044,0))=0,"n/a",((INDEX(Historical!$C$7:$C$1044,MATCH(B13,Historical!$B$7:$B$1044,0))/INDEX(Historical!$F$7:$F$1044,MATCH(B13,Historical!$B$7:$B$1044,0)))^(1/3)-1)*100) -> 6.5756717 | U13: =IF(INDEX(Historical!$H$7:$H$1044,MATCH(B13,Historical!$B$7:$B$1044,0))=0,"n/a",((INDEX(Historical!$C$7:$C$1044,MATCH(B13,Historical!$B$7:$B$1044,0))/INDEX(Historical!$H$7:$H$1044,MATCH(B13,Historical!$B$7:$B$1044,0)))^(1/5)-1)*100) -> 7.0854836 | V13: =IF(INDEX(Historical!$M$7:$M$1044,MATCH(B13,Historical!$B$7:$B$1044,0))=0,"n/a",((INDEX(Historical!$C$7:$C$1044,MATCH(B13,Historical!$B$7:$B$1044,0))/INDEX(Historical!$M$7:$M$1044,MATCH(B13,Historical!$B$7:$B$1044,0)))^(1/10)-1)*100) -> 13.76523 | W13: =IF(OR(U13<=0,U13="n/a",V13<=0,V13="n/a"),"n/a",U13/V13) -> 0.51473775 | X13: =IF(OR(AJ13<=0,AJ13="n/a",U13<=0,U13="n/a"),"n/a",U13/AJ13) -> 0.55967485 | Z13: =IF(OR(AC13<0.01,AC13="n/a"),"n/a",M13/AC13*100) -> 37.402597 | AA13: =IF(OR(AC13<0.01,AC13="n/a"),"n/a",I13/AC13) -> 16.062338 | AB13: 12 | AC13: 3.85 | AD13: 2.21 | AE13: 2.23 | AF13: 4.61 | AG13: 29.2 | AH13: 3.11 | AI13: 8.65 | AJ13: 12.66 | AK13: 6.5 | AL13: 8550 | AM13: 19.85 | AN13: 0.11 | AO13: =IF(U13="n/a","n/a",IF(AA13<0,"n/a",IF(AA13="n/a","n/a",J13+U13-AA13))) -> -6.6482642 | AP13: =IF(U13="n/a","n/a",J13+U13) -> 9.4140735 | AQ13: =IF(OR(AC13<0.01,AC13="n/a",AF13="n/a"),"n/a",(I13/SQRT(22.5*AC13*(I13/AF13))-1)*100) -> 81.410984 | AR13: =INDEX(Historical!$C$7:$C$1045,MATCH(B13,Historical!$B$7:$B$1045,0))*IF(AH13="n/a",1.03,IF(AH13<0,1.01,IF(AH13>10,1.1,(1+AH13/100)))) -> 1.422918 | AS13: =IF($AI13="n/a",1.03*AR13,IF($AI13<0,1.01*AR13,IF($AI13>10,1.1*AR13,(1+$AI13/100)*AR13))) -> 1.5460004 | AT13: =IF($AK13="n/a",1.03*AS13,IF($AK13<0,1.01*AS13,IF($AK13>10,1.1*AS13,(1+$AK13/100)*AS13))) -> 1.6464904 | AU13: =IF($AK13="n/a",1.03*AT13,IF($AK13<0,1.01*AT13,IF($AK13>10,1.1*AT13,(1+$AK13/100)*AT13))) -> 1.7535123 | AV13: =IF($AK13="n/a",1.03*AU13,IF($AK13<0,1.01*AU13,IF($AK13>10,1.1*AU13,(1+$AK13/100)*AU13))) -> 1.8674906 | AW13: =SUM(AR13:AV13) -> 8.2364118 | AX13: =AW13/I13*100 -> 13.318906 | AY13: 1.26 | AZ13: -0.48 | BA13: -24.46 | BB13: -8.99 | BC13: -11.44 | BE13: 1994 | BF13: =IF(BE13>2020,0,IF(BE13>2008,1,IF(BE13>2001,2,IF(BE13>1990,3,IF(BE13>1980,4,IF(BE13>1973,5,IF(BE13>1970,6,IF(BE13>1960,7,IF(BE13>1958,8,IF(BE13>1953,9,10)))))))))) -> 3 | BG13: 17.11 | BH13: USD | BI13: Corp
A14: Air Products and Chemicals, Inc. | B14: APD | C14: Materials | D14: Chemicals | E14: 44 | F14: 62 | G14: Y | H14: Y | I14: 300.05 | J14: =(M14/I14)*100 -> 2.4129312 | K14: 1.81 | L14: 4 | M14: =K14*L14 -> 7.24 | N14: B14 | O14: 1.79 | P14: 46113 | Q14: 46153 | R14: =(K14-O14)/O14*100 -> 1.1173184 | S14: =IF(INDEX(Historical!$D$7:$D1083,MATCH(B14,Historical!$B$7:$B$1044,0))=0,"n/a",(INDEX(Historical!$C$7:$C$1044,MATCH(B14,Historical!$B$7:$B$1044,0))/INDEX(Historical!$D$7:$D$1044,MATCH(B14,Historical!$B$7:$B$1044,0))-1)*100) -> 1.1331445 | T14: =IF(INDEX(Historical!$F$7:$F$1044,MATCH(B14,Historical!$B$7:$B$1044,0))=0,"n/a",((INDEX(Historical!$C$7:$C$1044,MATCH(B14,Historical!$B$7:$B$1044,0))/INDEX(Historical!$F$7:$F$1044,MATCH(B14,Historical!$B$7:$B$1044,0)))^(1/3)-1)*100) -> 3.9314609 | U14: =IF(INDEX(Historical!$H$7:$H$1044,MATCH(B14,Historical!$B$7:$B$1044,0))=0,"n/a",((INDEX(Historical!$C$7:$C$1044,MATCH(B14,Historical!$B$7:$B$1044,0))/INDEX(Historical!$H$7:$H$1044,MATCH(B14,Historical!$B$7:$B$1044,0)))^(1/5)-1)*100) -> 6.6285959 | V14: =IF(INDEX(Historical!$M$7:$M$1044,MATCH(B14,Historical!$B$7:$B$1044,0))=0,"n/a",((INDEX(Historical!$C$7:$C$1044,MATCH(B14,Historical!$B$7:$B$1044,0))/INDEX(Historical!$M$7:$M$1044,MATCH(B14,Historical!$B$7:$B$1044,0)))^(1/10)-1)*100) -> 8.3564638 | W14: =IF(OR(U14<=0,U14="n/a",V14<=0,V14="n/a"),"n/a",U14/V14) -> 0.79322978 | X14: =IF(OR(AJ14<=0,AJ14="n/a",U14<=0,U14="n/a"),"n/a",U14/AJ14) -> n/a | Z14: =IF(OR(AC14<0.01,AC14="n/a"),"n/a",M14/AC14*100) -> n/a | AA14: =IF(OR(AC14<0.01,AC14="n/a"),"n/a",I14/AC14) -> n/a | AB14: 9 | AC14: -1.5 | AD14: 2.46 | AE14: 5.47 | AF14: 4.33 | AG14: -2.03 | AH14: 9.24 | AI14: 7.89 | AJ14: n/a | AK14: 8.62 | AL14: 66810 | AM14: 0.42 | AN14: 1.18 | AO14: =IF(U14="n/a","n/a",IF(AA14<0,"n/a",IF(AA14="n/a","n/a",J14+U14-AA14))) -> n/a | AP14: =IF(U14="n/a","n/a",J14+U14) -> 9.0415271 | AQ14: =IF(OR(AC14<0.01,AC14="n/a",AF14="n/a"),"n/a",(I14/SQRT(22.5*AC14*(I14/AF14))-1)*100) -> n/a | AR14: =INDEX(Historical!$C$7:$C$1045,MATCH(B14,Historical!$B$7:$B$1045,0))*IF(AH14="n/a",1.03,IF(AH14<0,1.01,IF(AH14>10,1.1,(1+AH14/100)))) -> 7.799736 | AS14: =IF($AI14="n/a",1.03*AR14,IF($AI14<0,1.01*AR14,IF($AI14>10,1.1*AR14,(1+$AI14/100)*AR14))) -> 8.4151352 | AT14: =IF($AK14="n/a",1.03*AS14,IF($AK14<0,1.01*AS14,IF($AK14>10,1.1*AS14,(1+$AK14/100)*AS14))) -> 9.1405198 | AU14: =IF($AK14="n/a",1.03*AT14,IF($AK14<0,1.01*AT14,IF($AK14>10,1.1*AT14,(1+$AK14/100)*AT14))) -> 9.9284326 | AV14: =IF($AK14="n/a",1.03*AU14,IF($AK14<0,1.01*AU14,IF($AK14>10,1.1*AU14,(1+$AK14/100)*AU14))) -> 10.784264 | AW14: =SUM(AR14:AV14) -> 46.068087 | AX14: =AW14/I14*100 -> 15.35347 | AY14: 0.79 | AZ14: 30.96 | BA14: -2.36 | BB14: 4.02 | BC14: 9.3 | BE14: 1983 | BF14: =IF(BE14>2020,0,IF(BE14>2008,1,IF(BE14>2001,2,IF(BE14>1990,3,IF(BE14>1980,4,IF(BE14>1973,5,IF(BE14>1970,6,IF(BE14>1960,7,IF(BE14>1958,8,IF(BE14>1953,9,10)))))))))) -> 4 | BG14: -0.8 | BH14: USD | BI14: Corp
A15: Arrow Financial Corporation | B15: AROW | C15: Financials | D15: Banks | E15: 33 | F15: 99 | G15: N | H15: N | I15: 36.85 | J15: =(M15/I15)*100 -> 3.256445 | K15: 0.3 | L15: 4 | M15: =K15*L15 -> 1.2 | N15: C15 | O15: 0.29 | P15: 46064 | Q15: 46078 | R15: =(K15-O15)/O15*100 -> 3.4482759 | S15: =IF(INDEX(Historical!$D$7:$D1088,MATCH(B15,Historical!$B$7:$B$1044,0))=0,"n/a",(INDEX(Historical!$C$7:$C$1044,MATCH(B15,Historical!$B$7:$B$1044,0))/INDEX(Historical!$D$7:$D$1044,MATCH(B15,Historical!$B$7:$B$1044,0))-1)*100) -> 4.587156 | T15: =IF(INDEX(Historical!$F$7:$F$1044,MATCH(B15,Historical!$B$7:$B$1044,0))=0,"n/a",((INDEX(Historical!$C$7:$C$1044,MATCH(B15,Historical!$B$7:$B$1044,0))/INDEX(Historical!$F$7:$F$1044,MATCH(B15,Historical!$B$7:$B$1044,0)))^(1/3)-1)*100) -> 3.5868344 | U15: =IF(INDEX(Historical!$H$7:$H$1044,MATCH(B15,Historical!$B$7:$B$1044,0))=0,"n/a",((INDEX(Historical!$C$7:$C$1044,MATCH(B15,Historical!$B$7:$B$1044,0))/INDEX(Historical!$H$7:$H$1044,MATCH(B15,Historical!$B$7:$B$1044,0)))^(1/5)-1)*100) -> 4.1346043 | V15: =IF(INDEX(Historical!$M$7:$M$1044,MATCH(B15,Historical!$B$7:$B$1044,0))=0,"n/a",((INDEX(Historical!$C$7:$C$1044,MATCH(B15,Historical!$B$7:$B$1044,0))/INDEX(Historical!$M$7:$M$1044,MATCH(B15,Historical!$B$7:$B$1044,0)))^(1/10)-1)*100) -> 3.8971599 | W15: =IF(OR(U15<=0,U15="n/a",V15<=0,V15="n/a"),"n/a",U15/V15) -> 1.0609276 | X15: =IF(OR(AJ15<=0,AJ15="n/a",U15<=0,U15="n/a"),"n/a",U15/AJ15) -> 2.1534398 | Y15: Adj Stock dividend | Z15: =IF(OR(AC15<0.01,AC15="n/a"),"n/a",M15/AC15*100) -> 45.112782 | AA15: =IF(OR(AC15<0.01,AC15="n/a"),"n/a",I15/AC15) -> 13.853383 | AB15: 12 | AC15: 2.66 | AD15: n/a | AE15: 2.51 | AF15: 1.4 | AG15: 10.55 | AH15: 37.74 | AI15: 18.63 | AJ15: 1.92 | AK15: n/a | AL15: 608.45 | AM15: 2.95 | AN15: 0.08 | AO15: =IF(U15="n/a","n/a",IF(AA15<0,"n/a",IF(AA15="n/a","n/a",J15+U15-AA15))) -> -6.4623341 | AP15: =IF(U15="n/a","n/a",J15+U15) -> 7.3910494 | AQ15: =IF(OR(AC15<0.01,AC15="n/a",AF15="n/a"),"n/a",(I15/SQRT(22.5*AC15*(I15/AF15))-1)*100) -> -7.1566748 | AR15: =INDEX(Historical!$C$7:$C$1045,MATCH(B15,Historical!$B$7:$B$1045,0))*IF(AH15="n/a",1.03,IF(AH15<0,1.01,IF(AH15>10,1.1,(1+AH15/100)))) -> 1.254 | AS15: =IF($AI15="n/a",1.03*AR15,IF($AI15<0,1.01*AR15,IF($AI15>10,1.1*AR15,(1+$AI15/100)*AR15))) -> 1.3794 | AT15: =IF($AK15="n/a",1.03*AS15,IF($AK15<0,1.01*AS15,IF($AK15>10,1.1*AS15,(1+$AK15/100)*AS15))) -> 1.420782 | AU15: =IF($AK15="n/a",1.03*AT15,IF($AK15<0,1.01*AT15,IF($AK15>10,1.1*AT15,(1+$AK15/100)*AT15))) -> 1.4634055 | AV15: =IF($AK15="n/a",1.03*AU15,IF($AK15<0,1.01*AU15,IF($AK15>10,1.1*AU15,(1+$AK15/100)*AU15))) -> 1.5073076 | AW15: =SUM(AR15:AV15) -> 7.0248951 | AX15: =AW15/I15*100 -> 19.063487 | AY15: 0.76 | AZ15: 57.75 | BA15: -3.26 | BB15: 7.02 | BC15: 18.61 | BE15: 1994 | BF15: =IF(BE15>2020,0,IF(BE15>2008,1,IF(BE15>2001,2,IF(BE15>1990,3,IF(BE15>1980,4,IF(BE15>1973,5,IF(BE15>1970,6,IF(BE15>1960,7,IF(BE15>1958,8,IF(BE15>1953,9,10)))))))))) -> 3 | BG15: 1 | BH15: USD | BI15: Corp
A16: Artesian Resources Corporation | B16: ARTNA | C16: Utilities | D16: Water Utilities | E16: 33 | F16: 95 | G16: N | H16: N | I16: 31.31 | J16: =(M16/I16)*100 -> 4.0063877 | K16: 0.3136 | L16: 4 | M16: =K16*L16 -> 1.2544 | N16: B22 | O16: 0.3074 | P16: 45975 | Q16: 45985 | R16: =(K16-O16)/O16*100 -> 2.0169161 | S16: =IF(INDEX(Historical!$D$7:$D1089,MATCH(B16,Historical!$B$7:$B$1044,0))=0,"n/a",(INDEX(Historical!$C$7:$C$1044,MATCH(B16,Historical!$B$7:$B$1044,0))/INDEX(Historical!$D$7:$D$1044,MATCH(B16,Historical!$B$7:$B$1044,0))-1)*100) -> 4.0351916 | T16: =IF(INDEX(Historical!$F$7:$F$1044,MATCH(B16,Historical!$B$7:$B$1044,0))=0,"n/a",((INDEX(Historical!$C$7:$C$1044,MATCH(B16,Historical!$B$7:$B$1044,0))/INDEX(Historical!$F$7:$F$1044,MATCH(B16,Historical!$B$7:$B$1044,0)))^(1/3)-1)*100) -> 4.0503933 | U16: =IF(INDEX(Historical!$H$7:$H$1044,MATCH(B16,Historical!$B$7:$B$1044,0))=0,"n/a",((INDEX(Historical!$C$7:$C$1044,MATCH(B16,Historical!$B$7:$B$1044,0))/INDEX(Historical!$H$7:$H$1044,MATCH(B16,Historical!$B$7:$B$1044,0)))^(1/5)-1)*100) -> 4.101248 | V16: =IF(INDEX(Historical!$M$7:$M$1044,MATCH(B16,Historical!$B$7:$B$1044,0))=0,"n/a",((INDEX(Historical!$C$7:$C$1044,MATCH(B16,Historical!$B$7:$B$1044,0))/INDEX(Historical!$M$7:$M$1044,MATCH(B16,Historical!$B$7:$B$1044,0)))^(1/10)-1)*100) -> 3.4837305 | W16: =IF(OR(U16<=0,U16="n/a",V16<=0,V16="n/a"),"n/a",U16/V16) -> 1.1772576 | X16: =IF(OR(AJ16<=0,AJ16="n/a",U16<=0,U16="n/a"),"n/a",U16/AJ16) -> 0.95823552 | Z16: =IF(OR(AC16<0.01,AC16="n/a"),"n/a",M16/AC16*100) -> 56.760181 | AA16: =IF(OR(AC16<0.01,AC16="n/a"),"n/a",I16/AC16) -> 14.167421 | AB16: 12 | AC16: 2.21 | AD16: n/a | AE16: 2.88 | AF16: 1.29 | AG16: 9.33 | AH16: n/a | AI16: n/a | AJ16: 4.28 | AK16: n/a | AL16: 324.91 | AM16: 12 | AN16: 0.73 | AO16: =IF(U16="n/a","n/a",IF(AA16<0,"n/a",IF(AA16="n/a","n/a",J16+U16-AA16))) -> -6.0597851 | AP16: =IF(U16="n/a","n/a",J16+U16) -> 8.1076358 | AQ16: =IF(OR(AC16<0.01,AC16="n/a",AF16="n/a"),"n/a",(I16/SQRT(22.5*AC16*(I16/AF16))-1)*100) -> -9.874229 | AR16: =INDEX(Historical!$C$7:$C$1045,MATCH(B16,Historical!$B$7:$B$1045,0))*IF(AH16="n/a",1.03,IF(AH16<0,1.01,IF(AH16>10,1.1,(1+AH16/100)))) -> 1.266694 | AS16: =IF($AI16="n/a",1.03*AR16,IF($AI16<0,1.01*AR16,IF($AI16>10,1.1*AR16,(1+$AI16/100)*AR16))) -> 1.3046948 | AT16: =IF($AK16="n/a",1.03*AS16,IF($AK16<0,1.01*AS16,IF($AK16>10,1.1*AS16,(1+$AK16/100)*AS16))) -> 1.3438357 | AU16: =IF($AK16="n/a",1.03*AT16,IF($AK16<0,1.01*AT16,IF($AK16>10,1.1*AT16,(1+$AK16/100)*AT16))) -> 1.3841507 | AV16: =IF($AK16="n/a",1.03*AU16,IF($AK16<0,1.01*AU16,IF($AK16>10,1.1*AU16,(1+$AK16/100)*AU16))) -> 1.4256753 | AW16: =SUM(AR16:AV16) -> 6.7250505 | AX16: =AW16/I16*100 -> 21.478922 | AY16: 0.33 | AZ16: 2.66 | BA16: -13.48 | BB16: -3.67 | BC16: -3.98 | BE16: 1993 | BF16: =IF(BE16>2020,0,IF(BE16>2008,1,IF(BE16>2001,2,IF(BE16>1990,3,IF(BE16>1980,4,IF(BE16>1973,5,IF(BE16>1970,6,IF(BE16>1960,7,IF(BE16>1958,8,IF(BE16>1953,9,10)))))))))) -> 3 | BG16: 2.74 | BH16: USD | BI16: Corp
A17: Atmos Energy Corporation | B17: ATO | C17: Utilities | D17: Gas Utilities | E17: 42 | F17: 66 | G17: N | H17: N | I17: 189.98 | J17: =(M17/I17)*100 -> 2.1054848 | K17: 1 | L17: 4 | M17: =K17*L17 -> 4 | N17: C11 | O17: 0.87 | P17: 45985 | Q17: 45999 | R17: =(K17-O17)/O17*100 -> 14.942529 | S17: =IF(INDEX(Historical!$D$7:$D1092,MATCH(B17,Historical!$B$7:$B$1044,0))=0,"n/a",(INDEX(Historical!$C$7:$C$1044,MATCH(B17,Historical!$B$7:$B$1044,0))/INDEX(Historical!$D$7:$D$1044,MATCH(B17,Historical!$B$7:$B$1044,0))-1)*100) -> 9.8934551 | T17: =IF(INDEX(Historical!$F$7:$F$1044,MATCH(B17,Historical!$B$7:$B$1044,0))=0,"n/a",((INDEX(Historical!$C$7:$C$1044,MATCH(B17,Historical!$B$7:$B$1044,0))/INDEX(Historical!$F$7:$F$1044,MATCH(B17,Historical!$B$7:$B$1044,0)))^(1/3)-1)*100) -> 9.0990081 | U17: =IF(INDEX(Historical!$H$7:$H$1044,MATCH(B17,Historical!$B$7:$B$1044,0))=0,"n/a",((INDEX(Historical!$C$7:$C$1044,MATCH(B17,Historical!$B$7:$B$1044,0))/INDEX(Historical!$H$7:$H$1044,MATCH(B17,Historical!$B$7:$B$1044,0)))^(1/5)-1)*100) -> 8.9652119 | V17: =IF(INDEX(Historical!$M$7:$M$1044,MATCH(B17,Historical!$B$7:$B$1044,0))=0,"n/a",((INDEX(Historical!$C$7:$C$1044,MATCH(B17,Historical!$B$7:$B$1044,0))/INDEX(Historical!$M$7:$M$1044,MATCH(B17,Historical!$B$7:$B$1044,0)))^(1/10)-1)*100) -> 8.5452961 | W17: =IF(OR(U17<=0,U17="n/a",V17<=0,V17="n/a"),"n/a",U17/V17) -> 1.04914 | X17: =IF(OR(AJ17<=0,AJ17="n/a",U17<=0,U17="n/a"),"n/a",U17/AJ17) -> 1.0164639 | Z17: =IF(OR(AC17<0.01,AC17="n/a"),"n/a",M17/AC17*100) -> 52.083333 | AA17: =IF(OR(AC17<0.01,AC17="n/a"),"n/a",I17/AC17) -> 24.736979 | AB17: 9 | AC17: 7.68 | AD17: 2.44 | AE17: 6.45 | AF17: 2.2 | AG17: 9.23 | AH17: 11.43 | AI17: 6.78 | AJ17: 8.82 | AK17: 8.77 | AL17: 31430 | AM17: 0.45 | AN17: 0.67 | AO17: =IF(U17="n/a","n/a",IF(AA17<0,"n/a",IF(AA17="n/a","n/a",J17+U17-AA17))) -> -13.666282 | AP17: =IF(U17="n/a","n/a",J17+U17) -> 11.070697 | AQ17: =IF(OR(AC17<0.01,AC17="n/a",AF17="n/a"),"n/a",(I17/SQRT(22.5*AC17*(I17/AF17))-1)*100) -> 55.522566 | AR17: =INDEX(Historical!$C$7:$C$1045,MATCH(B17,Historical!$B$7:$B$1045,0))*IF(AH17="n/a",1.03,IF(AH17<0,1.01,IF(AH17>10,1.1,(1+AH17/100)))) -> 3.971 | AS17: =IF($AI17="n/a",1.03*AR17,IF($AI17<0,1.01*AR17,IF($AI17>10,1.1*AR17,(1+$AI17/100)*AR17))) -> 4.2402338 | AT17: =IF($AK17="n/a",1.03*AS17,IF($AK17<0,1.01*AS17,IF($AK17>10,1.1*AS17,(1+$AK17/100)*AS17))) -> 4.6121023 | AU17: =IF($AK17="n/a",1.03*AT17,IF($AK17<0,1.01*AT17,IF($AK17>10,1.1*AT17,(1+$AK17/100)*AT17))) -> 5.0165837 | AV17: =IF($AK17="n/a",1.03*AU17,IF($AK17<0,1.01*AU17,IF($AK17>10,1.1*AU17,(1+$AK17/100)*AU17))) -> 5.4565381 | AW17: =SUM(AR17:AV17) -> 23.296458 | AX17: =AW17/I17*100 -> 12.262584 | AY17: 0.64 | AZ17: 26.67 | BA17: -1.31 | BB17: 2.43 | BC17: 9.88 | BE17: 1985 | BF17: =IF(BE17>2020,0,IF(BE17>2008,1,IF(BE17>2001,2,IF(BE17>1990,3,IF(BE17>1980,4,IF(BE17>1973,5,IF(BE17>1970,6,IF(BE17>1960,7,IF(BE17>1958,8,IF(BE17>1953,9,10)))))))))) -> 4 | BG17: 4.44 | BH17: USD | BI17: Corp
A18: AptarGroup, Inc. | B18: ATR | C18: Materials | D18: Containers & Packaging | E18: 32 | F18: 109 | G18: - | H18: - | I18: 123.68 | J18: =(M18/I18)*100 -> 1.5523933 | K18: 0.48 | L18: 4 | M18: =K18*L18 -> 1.92 | N18: B23 | O18: 0.45 | P18: 45953 | Q18: 45974 | R18: =(K18-O18)/O18*100 -> 6.6666667 | S18: =IF(INDEX(Historical!$D$7:$D1093,MATCH(B18,Historical!$B$7:$B$1044,0))=0,"n/a",(INDEX(Historical!$C$7:$C$1044,MATCH(B18,Historical!$B$7:$B$1044,0))/INDEX(Historical!$D$7:$D$1044,MATCH(B18,Historical!$B$7:$B$1044,0))-1)*100) -> 6.3953488 | T18: =IF(INDEX(Historical!$F$7:$F$1044,MATCH(B18,Historical!$B$7:$B$1044,0))=0,"n/a",((INDEX(Historical!$C$7:$C$1044,MATCH(B18,Historical!$B$7:$B$1044,0))/INDEX(Historical!$F$7:$F$1044,MATCH(B18,Historical!$B$7:$B$1044,0)))^(1/3)-1)*100) -> 6.382249 | U18: =IF(INDEX(Historical!$H$7:$H$1044,MATCH(B18,Historical!$B$7:$B$1044,0))=0,"n/a",((INDEX(Historical!$C$7:$C$1044,MATCH(B18,Historical!$B$7:$B$1044,0))/INDEX(Historical!$H$7:$H$1044,MATCH(B18,Historical!$B$7:$B$1044,0)))^(1/5)-1)*100) -> 4.9102011 | V18: =IF(INDEX(Historical!$M$7:$M$1044,MATCH(B18,Historical!$B$7:$B$1044,0))=0,"n/a",((INDEX(Historical!$C$7:$C$1044,MATCH(B18,Historical!$B$7:$B$1044,0))/INDEX(Historical!$M$7:$M$1044,MATCH(B18,Historical!$B$7:$B$1044,0)))^(1/10)-1)*100) -> 4.8466657 | W18: =IF(OR(U18<=0,U18="n/a",V18<=0,V18="n/a"),"n/a",U18/V18) -> 1.0131091 | X18: =IF(OR(AJ18<=0,AJ18="n/a",U18<=0,U18="n/a"),"n/a",U18/AJ18) -> 0.38152301 | Z18: =IF(OR(AC18<0.01,AC18="n/a"),"n/a",M18/AC18*100) -> 32.653061 | AA18: =IF(OR(AC18<0.01,AC18="n/a"),"n/a",I18/AC18) -> 21.034014 | AB18: 12 | AC18: 5.88 | AD18: 2.4 | AE18: 2.09 | AF18: 2.98 | AG18: 15.28 | AH18: -2.99 | AI18: 16.06 | AJ18: 12.87 | AK18: 7.97 | AL18: 7890 | AM18: 0.72 | AN18: 0.58 | AO18: =IF(U18="n/a","n/a",IF(AA18<0,"n/a",IF(AA18="n/a","n/a",J18+U18-AA18))) -> -14.571419 | AP18: =IF(U18="n/a","n/a",J18+U18) -> 6.4625944 | AQ18: =IF(OR(AC18<0.01,AC18="n/a",AF18="n/a"),"n/a",(I18/SQRT(22.5*AC18*(I18/AF18))-1)*100) -> 66.908306 | AR18: =INDEX(Historical!$C$7:$C$1045,MATCH(B18,Historical!$B$7:$B$1045,0))*IF(AH18="n/a",1.03,IF(AH18<0,1.01,IF(AH18>10,1.1,(1+AH18/100)))) -> 1.8483 | AS18: =IF($AI18="n/a",1.03*AR18,IF($AI18<0,1.01*AR18,IF($AI18>10,1.1*AR18,(1+$AI18/100)*AR18))) -> 2.03313 | AT18: =IF($AK18="n/a",1.03*AS18,IF($AK18<0,1.01*AS18,IF($AK18>10,1.1*AS18,(1+$AK18/100)*AS18))) -> 2.1951705 | AU18: =IF($AK18="n/a",1.03*AT18,IF($AK18<0,1.01*AT18,IF($AK18>10,1.1*AT18,(1+$AK18/100)*AT18))) -> 2.3701255 | AV18: =IF($AK18="n/a",1.03*AU18,IF($AK18<0,1.01*AU18,IF($AK18>10,1.1*AU18,(1+$AK18/100)*AU18))) -> 2.5590246 | AW18: =SUM(AR18:AV18) -> 11.005751 | AX18: =AW18/I18*100 -> 8.8985693 | AY18: 0.43 | AZ18: 19.81 | BA18: -24.71 | BB18: -5.23 | BC18: -5.59 | BE18: 1994 | BF18: =IF(BE18>2020,0,IF(BE18>2008,1,IF(BE18>2001,2,IF(BE18>1990,3,IF(BE18>1980,4,IF(BE18>1973,5,IF(BE18>1970,6,IF(BE18>1960,7,IF(BE18>1958,8,IF(BE18>1953,9,10)))))))))) -> 3 | BG18: 8.11 | BH18: USD | BI18: Corp
A19: American States Water Company | B19: AWR | C19: Utilities | D19: Water Utilities | E19: 71 | F19: 1 | G19: N | H19: N | I19: 75.29 | J19: =(M19/I19)*100 -> 2.6776464 | K19: 0.504 | L19: 4 | M19: =K19*L19 -> 2.016 | N19: C01 | O19: 0.4655 | P19: 45884 | Q19: 45903 | R19: =(K19-O19)/O19*100 -> 8.2706767 | S19: =IF(INDEX(Historical!$D$7:$D1102,MATCH(B19,Historical!$B$7:$B$1044,0))=0,"n/a",(INDEX(Historical!$C$7:$C$1044,MATCH(B19,Historical!$B$7:$B$1044,0))/INDEX(Historical!$D$7:$D$1044,MATCH(B19,Historical!$B$7:$B$1044,0))-1)*100) -> 8.2635399 | T19: =IF(INDEX(Historical!$F$7:$F$1044,MATCH(B19,Historical!$B$7:$B$1044,0))=0,"n/a",((INDEX(Historical!$C$7:$C$1044,MATCH(B19,Historical!$B$7:$B$1044,0))/INDEX(Historical!$F$7:$F$1044,MATCH(B19,Historical!$B$7:$B$1044,0)))^(1/3)-1)*100) -> 8.3351332 | U19: =IF(INDEX(Historical!$H$7:$H$1044,MATCH(B19,Historical!$B$7:$B$1044,0))=0,"n/a",((INDEX(Historical!$C$7:$C$1044,MATCH(B19,Historical!$B$7:$B$1044,0))/INDEX(Historical!$H$7:$H$1044,MATCH(B19,Historical!$B$7:$B$1044,0)))^(1/5)-1)*100) -> 8.6609676 | V19: =IF(INDEX(Historical!$M$7:$M$1044,MATCH(B19,Historical!$B$7:$B$1044,0))=0,"n/a",((INDEX(Historical!$C$7:$C$1044,MATCH(B19,Historical!$B$7:$B$1044,0))/INDEX(Historical!$M$7:$M$1044,MATCH(B19,Historical!$B$7:$B$1044,0)))^(1/10)-1)*100) -> 8.2945591 | W19: =IF(OR(U19<=0,U19="n/a",V19<=0,V19="n/a"),"n/a",U19/V19) -> 1.0441746 | X19: =IF(OR(AJ19<=0,AJ19="n/a",U19<=0,U19="n/a"),"n/a",U19/AJ19) -> 1.1366099 | Z19: =IF(OR(AC19<0.01,AC19="n/a"),"n/a",M19/AC19*100) -> 59.821958 | AA19: =IF(OR(AC19<0.01,AC19="n/a"),"n/a",I19/AC19) -> 22.341246 | AB19: 12 | AC19: 3.37 | AD19: 2.62 | AE19: 4.48 | AF19: 2.81 | AG19: 13.22 | AH19: 10.09 | AI19: 2.83 | AJ19: 7.62 | AK19: 7.53 | AL19: 2950 | AM19: 0.97 | AN19: 0.9 | AO19: =IF(U19="n/a","n/a",IF(AA19<0,"n/a",IF(AA19="n/a","n/a",J19+U19-AA19))) -> -11.002632 | AP19: =IF(U19="n/a","n/a",J19+U19) -> 11.338614 | AQ19: =IF(OR(AC19<0.01,AC19="n/a",AF19="n/a"),"n/a",(I19/SQRT(22.5*AC19*(I19/AF19))-1)*100) -> 67.038122 | AR19: =INDEX(Historical!$C$7:$C$1045,MATCH(B19,Historical!$B$7:$B$1045,0))*IF(AH19="n/a",1.03,IF(AH19<0,1.01,IF(AH19>10,1.1,(1+AH19/100)))) -> 2.1329 | AS19: =IF($AI19="n/a",1.03*AR19,IF($AI19<0,1.01*AR19,IF($AI19>10,1.1*AR19,(1+$AI19/100)*AR19))) -> 2.1932611 | AT19: =IF($AK19="n/a",1.03*AS19,IF($AK19<0,1.01*AS19,IF($AK19>10,1.1*AS19,(1+$AK19/100)*AS19))) -> 2.3584136 | AU19: =IF($AK19="n/a",1.03*AT19,IF($AK19<0,1.01*AT19,IF($AK19>10,1.1*AT19,(1+$AK19/100)*AT19))) -> 2.5360022 | AV19: =IF($AK19="n/a",1.03*AU19,IF($AK19<0,1.01*AU19,IF($AK19>10,1.1*AU19,(1+$AK19/100)*AU19))) -> 2.7269631 | AW19: =SUM(AR19:AV19) -> 11.94754 | AX19: =AW19/I19*100 -> 15.868694 | AY19: 0.63 | AZ19: 8.41 | BA19: -9.22 | BB19: -0.57 | BC19: 1.52 | BE19: 1955 | BF19: =IF(BE19>2020,0,IF(BE19>2008,1,IF(BE19>2001,2,IF(BE19>1990,3,IF(BE19>1980,4,IF(BE19>1973,5,IF(BE19>1970,6,IF(BE19>1960,7,IF(BE19>1958,8,IF(BE19>1953,9,10)))))))))) -> 9 | BG19: 4.98 | BH19: USD | BI19: Corp
A20: BancFirst Corporation | B20: BANF | C20: Financials | D20: Banks | E20: 32 | F20: 108 | G20: - | H20: - | I20: 111.61 | J20: =(M20/I20)*100 -> 1.756115 | K20: 0.49 | L20: 4 | M20: =K20*L20 -> 1.96 | N20: A13 | O20: 0.46 | P20: 45930 | Q20: 45945 | R20: =(K20-O20)/O20*100 -> 6.5217391 | S20: =IF(INDEX(Historical!$D$7:$D1105,MATCH(B20,Historical!$B$7:$B$1044,0))=0,"n/a",(INDEX(Historical!$C$7:$C$1044,MATCH(B20,Historical!$B$7:$B$1044,0))/INDEX(Historical!$D$7:$D$1044,MATCH(B20,Historical!$B$7:$B$1044,0))-1)*100) -> 6.8571429 | T20: =IF(INDEX(Historical!$F$7:$F$1044,MATCH(B20,Historical!$B$7:$B$1044,0))=0,"n/a",((INDEX(Historical!$C$7:$C$1044,MATCH(B20,Historical!$B$7:$B$1044,0))/INDEX(Historical!$F$7:$F$1044,MATCH(B20,Historical!$B$7:$B$1044,0)))^(1/3)-1)*100) -> 8.1085304 | U20: =IF(INDEX(Historical!$H$7:$H$1044,MATCH(B20,Historical!$B$7:$B$1044,0))=0,"n/a",((INDEX(Historical!$C$7:$C$1044,MATCH(B20,Historical!$B$7:$B$1044,0))/INDEX(Historical!$H$7:$H$1044,MATCH(B20,Historical!$B$7:$B$1044,0)))^(1/5)-1)*100) -> 7.5423818 | V20: =IF(INDEX(Historical!$M$7:$M$1044,MATCH(B20,Historical!$B$7:$B$1044,0))=0,"n/a",((INDEX(Historical!$C$7:$C$1044,MATCH(B20,Historical!$B$7:$B$1044,0))/INDEX(Historical!$M$7:$M$1044,MATCH(B20,Historical!$B$7:$B$1044,0)))^(1/10)-1)*100) -> 10.483965 | W20: =IF(OR(U20<=0,U20="n/a",V20<=0,V20="n/a"),"n/a",U20/V20) -> 0.71942074 | X20: =IF(OR(AJ20<=0,AJ20="n/a",U20<=0,U20="n/a"),"n/a",U20/AJ20) -> 0.40012636 | Z20: =IF(OR(AC20<0.01,AC20="n/a"),"n/a",M20/AC20*100) -> 26.849315 | AA20: =IF(OR(AC20<0.01,AC20="n/a"),"n/a",I20/AC20) -> 15.289041 | AB20: 12 | AC20: 7.3 | AD20: n/a | AE20: 4.23 | AF20: 1.97 | AG20: 13.85 | AH20: 2.86 | AI20: 0.05 | AJ20: 18.85 | AK20: n/a | AL20: 3750 | AM20: 37.13 | AN20: 0.07 | AO20: =IF(U20="n/a","n/a",IF(AA20<0,"n/a",IF(AA20="n/a","n/a",J20+U20-AA20))) -> -5.9905442 | AP20: =IF(U20="n/a","n/a",J20+U20) -> 9.2984969 | AQ20: =IF(OR(AC20<0.01,AC20="n/a",AF20="n/a"),"n/a",(I20/SQRT(22.5*AC20*(I20/AF20))-1)*100) -> 15.699632 | AR20: =INDEX(Historical!$C$7:$C$1045,MATCH(B20,Historical!$B$7:$B$1045,0))*IF(AH20="n/a",1.03,IF(AH20<0,1.01,IF(AH20>10,1.1,(1+AH20/100)))) -> 1.923482 | AS20: =IF($AI20="n/a",1.03*AR20,IF($AI20<0,1.01*AR20,IF($AI20>10,1.1*AR20,(1+$AI20/100)*AR20))) -> 1.9244437 | AT20: =IF($AK20="n/a",1.03*AS20,IF($AK20<0,1.01*AS20,IF($AK20>10,1.1*AS20,(1+$AK20/100)*AS20))) -> 1.9821771 | AU20: =IF($AK20="n/a",1.03*AT20,IF($AK20<0,1.01*AT20,IF($AK20>10,1.1*AT20,(1+$AK20/100)*AT20))) -> 2.0416424 | AV20: =IF($AK20="n/a",1.03*AU20,IF($AK20<0,1.01*AU20,IF($AK20>10,1.1*AU20,(1+$AK20/100)*AU20))) -> 2.1028916 | AW20: =SUM(AR20:AV20) -> 9.9746368 | AX20: =AW20/I20*100 -> 8.9370458 | AY20: 0.62 | AZ20: 9.98 | BA20: -19.57 | BB20: 0.65 | BC20: -4.47 | BE20: 1994 | BF20: =IF(BE20>2020,0,IF(BE20>2008,1,IF(BE20>2001,2,IF(BE20>1990,3,IF(BE20>1980,4,IF(BE20>1973,5,IF(BE20>1970,6,IF(BE20>1960,7,IF(BE20>1958,8,IF(BE20>1953,9,10)))))))))) -> 3 | BG20: 1.7 | BH20: USD | BI20: Corp
A21: Becton, Dickinson and Company | B21: BDX | C21: Health Care | D21: Health Care Equipment & Supplies | E21: 54 | F21: 36 | G21: N | H21: N | I21: 149.04 | J21: =(M21/I21)*100 -> 2.8180354 | K21: 1.05 | L21: 4 | M21: =K21*L21 -> 4.2 | N21: C29 | O21: 1.04 | P21: 45999 | Q21: 46022 | R21: =(K21-O21)/O21*100 -> 0.96153846 | S21: =IF(INDEX(Historical!$D$7:$D1111,MATCH(B21,Historical!$B$7:$B$1044,0))=0,"n/a",(INDEX(Historical!$C$7:$C$1044,MATCH(B21,Historical!$B$7:$B$1044,0))/INDEX(Historical!$D$7:$D$1044,MATCH(B21,Historical!$B$7:$B$1044,0))-1)*100) -> 7.1979434 | T21: =IF(INDEX(Historical!$F$7:$F$1044,MATCH(B21,Historical!$B$7:$B$1044,0))=0,"n/a",((INDEX(Historical!$C$7:$C$1044,MATCH(B21,Historical!$B$7:$B$1044,0))/INDEX(Historical!$F$7:$F$1044,MATCH(B21,Historical!$B$7:$B$1044,0)))^(1/3)-1)*100) -> 5.8110759 | U21: =IF(INDEX(Historical!$H$7:$H$1044,MATCH(B21,Historical!$B$7:$B$1044,0))=0,"n/a",((INDEX(Historical!$C$7:$C$1044,MATCH(B21,Historical!$B$7:$B$1044,0))/INDEX(Historical!$H$7:$H$1044,MATCH(B21,Historical!$B$7:$B$1044,0)))^(1/5)-1)*100) -> 5.4380136 | V21: =IF(INDEX(Historical!$M$7:$M$1044,MATCH(B21,Historical!$B$7:$B$1044,0))=0,"n/a",((INDEX(Historical!$C$7:$C$1044,MATCH(B21,Historical!$B$7:$B$1044,0))/INDEX(Historical!$M$7:$M$1044,MATCH(B21,Historical!$B$7:$B$1044,0)))^(1/10)-1)*100) -> 5.4192919 | W21: =IF(OR(U21<=0,U21="n/a",V21<=0,V21="n/a"),"n/a",U21/V21) -> 1.0034546 | X21: =IF(OR(AJ21<=0,AJ21="n/a",U21<=0,U21="n/a"),"n/a",U21/AJ21) -> 0.33057833 | Y21: FY Streak | Z21: =IF(OR(AC21<0.01,AC21="n/a"),"n/a",M21/AC21*100) -> 68.627451 | AA21: =IF(OR(AC21<0.01,AC21="n/a"),"n/a",I21/AC21) -> 24.352941 | AB21: 9 | AC21: 6.12 | AD21: 1.37 | AE21: 1.94 | AF21: 1.68 | AG21: 6.96 | AH21: 10.36 | AI21: 7.68 | AJ21: 16.45 | AK21: 8.07 | AL21: 42440 | AM21: 0.19 | AN21: 0.77 | AO21: =IF(U21="n/a","n/a",IF(AA21<0,"n/a",IF(AA21="n/a","n/a",J21+U21-AA21))) -> -16.096892 | AP21: =IF(U21="n/a","n/a",J21+U21) -> 8.256049 | AQ21: =IF(OR(AC21<0.01,AC21="n/a",AF21="n/a"),"n/a",(I21/SQRT(22.5*AC21*(I21/AF21))-1)*100) -> 34.846318 | AR21: =INDEX(Historical!$C$7:$C$1045,MATCH(B21,Historical!$B$7:$B$1045,0))*IF(AH21="n/a",1.03,IF(AH21<0,1.01,IF(AH21>10,1.1,(1+AH21/100)))) -> 4.587 | AS21: =IF($AI21="n/a",1.03*AR21,IF($AI21<0,1.01*AR21,IF($AI21>10,1.1*AR21,(1+$AI21/100)*AR21))) -> 4.9392816 | AT21: =IF($AK21="n/a",1.03*AS21,IF($AK21<0,1.01*AS21,IF($AK21>10,1.1*AS21,(1+$AK21/100)*AS21))) -> 5.3378816 | AU21: =IF($AK21="n/a",1.03*AT21,IF($AK21<0,1.01*AT21,IF($AK21>10,1.1*AT21,(1+$AK21/100)*AT21))) -> 5.7686487 | AV21: =IF($AK21="n/a",1.03*AU21,IF($AK21<0,1.01*AU21,IF($AK21>10,1.1*AU21,(1+$AK21/100)*AU21))) -> 6.2341786 | AW21: =SUM(AR21:AV21) -> 26.866991 | AX21: =AW21/I21*100 -> 18.026698 | AY21: 0.22 | AZ21: 16.86 | BA21: -20.45 | BB21: -7.59 | BC21: -3.32 | BE21: 1973 | BF21: =IF(BE21>2020,0,IF(BE21>2008,1,IF(BE21>2001,2,IF(BE21>1990,3,IF(BE21>1980,4,IF(BE21>1973,5,IF(BE21>1970,6,IF(BE21>1960,7,IF(BE21>1958,8,IF(BE21>1953,9,10)))))))))) -> 6 | BG21: 3.21 | BH21: USD | BI21: Corp
A22: Franklin Resources, Inc. | B22: BEN | C22: Financials | D22: Capital Markets | E22: 46 | F22: 58 | G22: N | H22: Y | I22: 29.97 | J22: =(M22/I22)*100 -> 4.4044044 | K22: 0.33 | L22: 4 | M22: =K22*L22 -> 1.32 | N22: A10 | O22: 0.32 | P22: 46021 | Q22: 46031 | R22: =(K22-O22)/O22*100 -> 3.125 | S22: =IF(INDEX(Historical!$D$7:$D1112,MATCH(B22,Historical!$B$7:$B$1044,0))=0,"n/a",(INDEX(Historical!$C$7:$C$1044,MATCH(B22,Historical!$B$7:$B$1044,0))/INDEX(Historical!$D$7:$D$1044,MATCH(B22,Historical!$B$7:$B$1044,0))-1)*100) -> 3.2258065 | T22: =IF(INDEX(Historical!$F$7:$F$1044,MATCH(B22,Historical!$B$7:$B$1044,0))=0,"n/a",((INDEX(Historical!$C$7:$C$1044,MATCH(B22,Historical!$B$7:$B$1044,0))/INDEX(Historical!$F$7:$F$1044,MATCH(B22,Historical!$B$7:$B$1044,0)))^(1/3)-1)*100) -> 3.3357653 | U22: =IF(INDEX(Historical!$H$7:$H$1044,MATCH(B22,Historical!$B$7:$B$1044,0))=0,"n/a",((INDEX(Historical!$C$7:$C$1044,MATCH(B22,Historical!$B$7:$B$1044,0))/INDEX(Historical!$H$7:$H$1044,MATCH(B22,Historical!$B$7:$B$1044,0)))^(1/5)-1)*100) -> 3.4563716 | V22: =IF(INDEX(Historical!$M$7:$M$1044,MATCH(B22,Historical!$B$7:$B$1044,0))=0,"n/a",((INDEX(Historical!$C$7:$C$1044,MATCH(B22,Historical!$B$7:$B$1044,0))/INDEX(Historical!$M$7:$M$1044,MATCH(B22,Historical!$B$7:$B$1044,0)))^(1/10)-1)*100) -> 7.8712899 | W22: =IF(OR(U22<=0,U22="n/a",V22<=0,V22="n/a"),"n/a",U22/V22) -> 0.43911121 | X22: =IF(OR(AJ22<=0,AJ22="n/a",U22<=0,U22="n/a"),"n/a",U22/AJ22) -> n/a | Z22: =IF(OR(AC22<0.01,AC22="n/a"),"n/a",M22/AC22*100) -> 100.76336 | AA22: =IF(OR(AC22<0.01,AC22="n/a"),"n/a",I22/AC22) -> 22.877863 | AB22: 9 | AC22: 1.31 | AD22: 0.86 | AE22: 1.74 | AF22: 1.28 | AG22: 5.54 | AH22: 22.64 | AI22: 7.18 | AJ22: -10.54 | AK22: 11.89 | AL22: 15570 | AM22: 47.04 | AN22: 1.27 | AO22: =IF(U22="n/a","n/a",IF(AA22<0,"n/a",IF(AA22="n/a","n/a",J22+U22-AA22))) -> -15.017087 | AP22: =IF(U22="n/a","n/a",J22+U22) -> 7.860776 | AQ22: =IF(OR(AC22<0.01,AC22="n/a",AF22="n/a"),"n/a",(I22/SQRT(22.5*AC22*(I22/AF22))-1)*100) -> 14.083136 | AR22: =INDEX(Historical!$C$7:$C$1045,MATCH(B22,Historical!$B$7:$B$1045,0))*IF(AH22="n/a",1.03,IF(AH22<0,1.01,IF(AH22>10,1.1,(1+AH22/100)))) -> 1.408 | AS22: =IF($AI22="n/a",1.03*AR22,IF($AI22<0,1.01*AR22,IF($AI22>10,1.1*AR22,(1+$AI22/100)*AR22))) -> 1.5090944 | AT22: =IF($AK22="n/a",1.03*AS22,IF($AK22<0,1.01*AS22,IF($AK22>10,1.1*AS22,(1+$AK22/100)*AS22))) -> 1.6600038 | AU22: =IF($AK22="n/a",1.03*AT22,IF($AK22<0,1.01*AT22,IF($AK22>10,1.1*AT22,(1+$AK22/100)*AT22))) -> 1.8260042 | AV22: =IF($AK22="n/a",1.03*AU22,IF($AK22<0,1.01*AU22,IF($AK22>10,1.1*AU22,(1+$AK22/100)*AU22))) -> 2.0086046 | AW22: =SUM(AR22:AV22) -> 8.4117071 | AX22: =AW22/I22*100 -> 28.067091 | AY22: 1.58 | AZ22: 64.99 | BA22: -1.02 | BB22: 16.51 | BC22: 21.62 | BE22: 1981 | BF22: =IF(BE22>2020,0,IF(BE22>2008,1,IF(BE22>2001,2,IF(BE22>1990,3,IF(BE22>1980,4,IF(BE22>1973,5,IF(BE22>1970,6,IF(BE22>1960,7,IF(BE22>1958,8,IF(BE22>1953,9,10)))))))))) -> 4 | BG22: 2.05 | BH22: USD | BI22: Corp
A23: Brown-Forman Corporation | B23: BF-B | C23: Consumer Staples | D23: Beverages | E23: 41 | F23: 67 | G23: Y | H23: Y | I23: 25.77 | J23: =(M23/I23)*100 -> 3.5855646 | K23: 0.231 | L23: 4 | M23: =K23*L23 -> 0.924 | N23: A02 | O23: 0.2265 | P23: 45996 | Q23: 46024 | R23: =(K23-O23)/O23*100 -> 1.986755 | S23: =IF(INDEX(Historical!$D$7:$D1114,MATCH(B23,Historical!$B$7:$B$1044,0))=0,"n/a",(INDEX(Historical!$C$7:$C$1044,MATCH(B23,Historical!$B$7:$B$1044,0))/INDEX(Historical!$D$7:$D$1044,MATCH(B23,Historical!$B$7:$B$1044,0))-1)*100) -> 3.9944904 | T23: =IF(INDEX(Historical!$F$7:$F$1044,MATCH(B23,Historical!$B$7:$B$1044,0))=0,"n/a",((INDEX(Historical!$C$7:$C$1044,MATCH(B23,Historical!$B$7:$B$1044,0))/INDEX(Historical!$F$7:$F$1044,MATCH(B23,Historical!$B$7:$B$1044,0)))^(1/3)-1)*100) -> 6.3128149 | U23: =IF(INDEX(Historical!$H$7:$H$1044,MATCH(B23,Historical!$B$7:$B$1044,0))=0,"n/a",((INDEX(Historical!$C$7:$C$1044,MATCH(B23,Historical!$B$7:$B$1044,0))/INDEX(Historical!$H$7:$H$1044,MATCH(B23,Historical!$B$7:$B$1044,0)))^(1/5)-1)*100) -> 5.379022 | V23: =IF(INDEX(Historical!$M$7:$M$1044,MATCH(B23,Historical!$B$7:$B$1044,0))=0,"n/a",((INDEX(Historical!$C$7:$C$1044,MATCH(B23,Historical!$B$7:$B$1044,0))/INDEX(Historical!$M$7:$M$1044,MATCH(B23,Historical!$B$7:$B$1044,0)))^(1/10)-1)*100) -> 5.8318792 | W23: =IF(OR(U23<=0,U23="n/a",V23<=0,V23="n/a"),"n/a",U23/V23) -> 0.92234798 | X23: =IF(OR(AJ23<=0,AJ23="n/a",U23<=0,U23="n/a"),"n/a",U23/AJ23) -> 4.1061237 | Z23: =IF(OR(AC23<0.01,AC23="n/a"),"n/a",M23/AC23*100) -> 53.72093 | AA23: =IF(OR(AC23<0.01,AC23="n/a"),"n/a",I23/AC23) -> 14.982558 | AB23: 4 | AC23: 1.72 | AD23: n/a | AE23: 3.04 | AF23: 2.9 | AG23: 20.42 | AH23: -4.74 | AI23: -3.22 | AJ23: 1.31 | AK23: -2.18 | AL23: 11910 | AM23: 39.03 | AN23: 0.67 | AO23: =IF(U23="n/a","n/a",IF(AA23<0,"n/a",IF(AA23="n/a","n/a",J23+U23-AA23))) -> -6.0179715 | AP23: =IF(U23="n/a","n/a",J23+U23) -> 8.9645867 | AQ23: =IF(OR(AC23<0.01,AC23="n/a",AF23="n/a"),"n/a",(I23/SQRT(22.5*AC23*(I23/AF23))-1)*100) -> 38.963494 | AR23: =INDEX(Historical!$C$7:$C$1045,MATCH(B23,Historical!$B$7:$B$1045,0))*IF(AH23="n/a",1.03,IF(AH23<0,1.01,IF(AH23>10,1.1,(1+AH23/100)))) -> 0.91506 | AS23: =IF($AI23="n/a",1.03*AR23,IF($AI23<0,1.01*AR23,IF($AI23>10,1.1*AR23,(1+$AI23/100)*AR23))) -> 0.9242106 | AT23: =IF($AK23="n/a",1.03*AS23,IF($AK23<0,1.01*AS23,IF($AK23>10,1.1*AS23,(1+$AK23/100)*AS23))) -> 0.93345271 | AU23: =IF($AK23="n/a",1.03*AT23,IF($AK23<0,1.01*AT23,IF($AK23>10,1.1*AT23,(1+$AK23/100)*AT23))) -> 0.94278723 | AV23: =IF($AK23="n/a",1.03*AU23,IF($AK23<0,1.01*AU23,IF($AK23>10,1.1*AU23,(1+$AK23/100)*AU23))) -> 0.95221511 | AW23: =SUM(AR23:AV23) -> 4.6677256 | AX23: =AW23/I23*100 -> 18.113022 | AY23: 0.33 | AZ23: 13.98 | BA23: -28.77 | BB23: -3.9 | BC23: -7.96 | BE23: 1985 | BF23: =IF(BE23>2020,0,IF(BE23>2008,1,IF(BE23>2001,2,IF(BE23>1990,3,IF(BE23>1980,4,IF(BE23>1973,5,IF(BE23>1970,6,IF(BE23>1960,7,IF(BE23>1958,8,IF(BE23>1953,9,10)))))))))) -> 4 | BG23: 9.86 | BH23: USD | BI23: Corp
A24: Black Hills Corporation | B24: BKH | C24: Utilities | D24: Multi-Utilities | E24: 56 | F24: 28 | G24: N | H24: N | I24: 75.29 | J24: =(M24/I24)*100 -> 3.7348918 | K24: 0.703 | L24: 4 | M24: =K24*L24 -> 2.812 | N24: C01 | O24: 0.676 | P24: 46070 | Q24: 46082 | R24: =(K24-O24)/O24*100 -> 3.9940828 | S24: =IF(INDEX(Historical!$D$7:$D1120,MATCH(B24,Historical!$B$7:$B$1044,0))=0,"n/a",(INDEX(Historical!$C$7:$C$1044,MATCH(B24,Historical!$B$7:$B$1044,0))/INDEX(Historical!$D$7:$D$1044,MATCH(B24,Historical!$B$7:$B$1044,0))-1)*100) -> 4 | T24: =IF(INDEX(Historical!$F$7:$F$1044,MATCH(B24,Historical!$B$7:$B$1044,0))=0,"n/a",((INDEX(Historical!$C$7:$C$1044,MATCH(B24,Historical!$B$7:$B$1044,0))/INDEX(Historical!$F$7:$F$1044,MATCH(B24,Historical!$B$7:$B$1044,0)))^(1/3)-1)*100) -> 3.9114045 | U24: =IF(INDEX(Historical!$H$7:$H$1044,MATCH(B24,Historical!$B$7:$B$1044,0))=0,"n/a",((INDEX(Historical!$C$7:$C$1044,MATCH(B24,Historical!$B$7:$B$1044,0))/INDEX(Historical!$H$7:$H$1044,MATCH(B24,Historical!$B$7:$B$1044,0)))^(1/5)-1)*100) -> 4.4983398 | V24: =IF(INDEX(Historical!$M$7:$M$1044,MATCH(B24,Historical!$B$7:$B$1044,0))=0,"n/a",((INDEX(Historical!$C$7:$C$1044,MATCH(B24,Historical!$B$7:$B$1044,0))/INDEX(Historical!$M$7:$M$1044,MATCH(B24,Historical!$B$7:$B$1044,0)))^(1/10)-1)*100) -> 5.2565588 | W24: =IF(OR(U24<=0,U24="n/a",V24<=0,V24="n/a"),"n/a",U24/V24) -> 0.85575754 | X24: =IF(OR(AJ24<=0,AJ24="n/a",U24<=0,U24="n/a"),"n/a",U24/AJ24) -> 2.513039 | Z24: =IF(OR(AC24<0.01,AC24="n/a"),"n/a",M24/AC24*100) -> 70.653266 | AA24: =IF(OR(AC24<0.01,AC24="n/a"),"n/a",I24/AC24) -> 18.917085 | AB24: 12 | AC24: 3.98 | AD24: 2.45 | AE24: 2.48 | AF24: 1.49 | AG24: 7.96 | AH24: 6.16 | AI24: 6.09 | AJ24: 1.79 | AK24: 6.65 | AL24: 5730 | AM24: 0.46 | AN24: 1.23 | AO24: =IF(U24="n/a","n/a",IF(AA24<0,"n/a",IF(AA24="n/a","n/a",J24+U24-AA24))) -> -10.683854 | AP24: =IF(U24="n/a","n/a",J24+U24) -> 8.2332315 | AQ24: =IF(OR(AC24<0.01,AC24="n/a",AF24="n/a"),"n/a",(I24/SQRT(22.5*AC24*(I24/AF24))-1)*100) -> 11.925486 | AR24: =INDEX(Historical!$C$7:$C$1045,MATCH(B24,Historical!$B$7:$B$1045,0))*IF(AH24="n/a",1.03,IF(AH24<0,1.01,IF(AH24>10,1.1,(1+AH24/100)))) -> 2.8705664 | AS24: =IF($AI24="n/a",1.03*AR24,IF($AI24<0,1.01*AR24,IF($AI24>10,1.1*AR24,(1+$AI24/100)*AR24))) -> 3.0453839 | AT24: =IF($AK24="n/a",1.03*AS24,IF($AK24<0,1.01*AS24,IF($AK24>10,1.1*AS24,(1+$AK24/100)*AS24))) -> 3.2479019 | AU24: =IF($AK24="n/a",1.03*AT24,IF($AK24<0,1.01*AT24,IF($AK24>10,1.1*AT24,(1+$AK24/100)*AT24))) -> 3.4638874 | AV24: =IF($AK24="n/a",1.03*AU24,IF($AK24<0,1.01*AU24,IF($AK24>10,1.1*AU24,(1+$AK24/100)*AU24))) -> 3.6942359 | AW24: =SUM(AR24:AV24) -> 16.321976 | AX24: =AW24/I24*100 -> 21.678809 | AY24: 0.72 | AZ24: 35.69 | BA24: -4.32 | BB24: 3.62 | BC24: 11.88 | BE24: 1972 | BF24: =IF(BE24>2020,0,IF(BE24>2008,1,IF(BE24>2001,2,IF(BE24>1990,3,IF(BE24>1980,4,IF(BE24>1973,5,IF(BE24>1970,6,IF(BE24>1960,7,IF(BE24>1958,8,IF(BE24>1953,9,10)))))))))) -> 6 | BG24: 2.7 | BH24: USD | BI24: Corp
A25: Bank of Utica | B25: BKUTK | C25: Financials | D25: Banks | E25: 26 | F25: 142 | G25: - | H25: - | I25: 659 | J25: =(M25/I25)*100 -> 2.9590288 | K25: 9.75 | L25: 2 | M25: =K25*L25 -> 19.5 | N25: JaJl | O25: 9.5 | P25: 46022 | Q25: 46042 | R25: =(K25-O25)/O25*100 -> 2.6315789 | S25: =IF(INDEX(Historical!$D$7:$D1122,MATCH(B25,Historical!$B$7:$B$1044,0))=0,"n/a",(INDEX(Historical!$C$7:$C$1044,MATCH(B25,Historical!$B$7:$B$1044,0))/INDEX(Historical!$D$7:$D$1044,MATCH(B25,Historical!$B$7:$B$1044,0))-1)*100) -> 2.7027027 | T25: =IF(INDEX(Historical!$F$7:$F$1044,MATCH(B25,Historical!$B$7:$B$1044,0))=0,"n/a",((INDEX(Historical!$C$7:$C$1044,MATCH(B25,Historical!$B$7:$B$1044,0))/INDEX(Historical!$F$7:$F$1044,MATCH(B25,Historical!$B$7:$B$1044,0)))^(1/3)-1)*100) -> 2.7791884 | U25: =IF(INDEX(Historical!$H$7:$H$1044,MATCH(B25,Historical!$B$7:$B$1044,0))=0,"n/a",((INDEX(Historical!$C$7:$C$1044,MATCH(B25,Historical!$B$7:$B$1044,0))/INDEX(Historical!$H$7:$H$1044,MATCH(B25,Historical!$B$7:$B$1044,0)))^(1/5)-1)*100) -> 4.156021 | V25: =IF(INDEX(Historical!$M$7:$M$1044,MATCH(B25,Historical!$B$7:$B$1044,0))=0,"n/a",((INDEX(Historical!$C$7:$C$1044,MATCH(B25,Historical!$B$7:$B$1044,0))/INDEX(Historical!$M$7:$M$1044,MATCH(B25,Historical!$B$7:$B$1044,0)))^(1/10)-1)*100) -> 4.5296213 | W25: =IF(OR(U25<=0,U25="n/a",V25<=0,V25="n/a"),"n/a",U25/V25) -> 0.91752063 | X25: =IF(OR(AJ25<=0,AJ25="n/a",U25<=0,U25="n/a"),"n/a",U25/AJ25) -> n/a | Z25: =IF(OR(AC25<0.01,AC25="n/a"),"n/a",M25/AC25*100) -> n/a | AA25: =IF(OR(AC25<0.01,AC25="n/a"),"n/a",I25/AC25) -> n/a | AB25: 12 | AC25: n/a | AD25: n/a | AE25: n/a | AF25: n/a | AG25: n/a | AH25: n/a | AI25: n/a | AJ25: n/a | AK25: n/a | AL25: n/a | AM25: n/a | AN25: n/a | AO25: =IF(U25="n/a","n/a",IF(AA25<0,"n/a",IF(AA25="n/a","n/a",J25+U25-AA25))) -> n/a | AP25: =IF(U25="n/a","n/a",J25+U25) -> 7.1150498 | AQ25: =IF(OR(AC25<0.01,AC25="n/a",AF25="n/a"),"n/a",(I25/SQRT(22.5*AC25*(I25/AF25))-1)*100) -> n/a | AR25: =INDEX(Historical!$C$7:$C$1045,MATCH(B25,Historical!$B$7:$B$1045,0))*IF(AH25="n/a",1.03,IF(AH25<0,1.01,IF(AH25>10,1.1,(1+AH25/100)))) -> 19.57 | AS25: =IF($AI25="n/a",1.03*AR25,IF($AI25<0,1.01*AR25,IF($AI25>10,1.1*AR25,(1+$AI25/100)*AR25))) -> 20.1571 | AT25: =IF($AK25="n/a",1.03*AS25,IF($AK25<0,1.01*AS25,IF($AK25>10,1.1*AS25,(1+$AK25/100)*AS25))) -> 20.761813 | AU25: =IF($AK25="n/a",1.03*AT25,IF($AK25<0,1.01*AT25,IF($AK25>10,1.1*AT25,(1+$AK25/100)*AT25))) -> 21.384667 | AV25: =IF($AK25="n/a",1.03*AU25,IF($AK25<0,1.01*AU25,IF($AK25>10,1.1*AU25,(1+$AK25/100)*AU25))) -> 22.026207 | AW25: =SUM(AR25:AV25) -> 103.89979 | AX25: =AW25/I25*100 -> 15.76628 | AY25: n/a | AZ25: n/a | BA25: n/a | BB25: n/a | BC25: n/a | BD25: OTC | BE25: 2001 | BF25: =IF(BE25>2020,0,IF(BE25>2008,1,IF(BE25>2001,2,IF(BE25>1990,3,IF(BE25>1980,4,IF(BE25>1973,5,IF(BE25>1970,6,IF(BE25>1960,7,IF(BE25>1958,8,IF(BE25>1953,9,10)))))))))) -> 3 | BG25: n/a | BH25: USD | BI25: Corp
